[ERROR] 2022-08-26 16:54:54,376 - Traceback (most recent call last):
  File "C:\Users\shuitt\.pyenv\pyenv-win\versions\3.9.6\lib\site-packages\websocket\_app.py", line 327, in run_forever
    self.sock.connect(
  File "C:\Users\shuitt\.pyenv\pyenv-win\versions\3.9.6\lib\site-packages\websocket\_core.py", line 244, in connect
    self.sock, addrs = connect(url, self.sock_opt, proxy_info(**options),
  File "C:\Users\shuitt\.pyenv\pyenv-win\versions\3.9.6\lib\site-packages\websocket\_http.py", line 130, in connect
    sock = _open_socket(addrinfo_list, options.sockopt, options.timeout)
  File "C:\Users\shuitt\.pyenv\pyenv-win\versions\3.9.6\lib\site-packages\websocket\_http.py", line 205, in _open_socket
    raise err
  File "C:\Users\shuitt\.pyenv\pyenv-win\versions\3.9.6\lib\site-packages\websocket\_http.py", line 185, in _open_socket
    sock.connect(address)
ConnectionRefusedError: [WinError 10061] 対象のコンピューターによって拒否されたため、接続できませんでした。
 (main.py)
[ERROR] 2022-08-26 16:54:58,583 - Traceback (most recent call last):
  File "C:\Users\shuitt\.pyenv\pyenv-win\versions\3.9.6\lib\site-packages\websocket\_app.py", line 327, in run_forever
    self.sock.connect(
  File "C:\Users\shuitt\.pyenv\pyenv-win\versions\3.9.6\lib\site-packages\websocket\_core.py", line 244, in connect
    self.sock, addrs = connect(url, self.sock_opt, proxy_info(**options),
  File "C:\Users\shuitt\.pyenv\pyenv-win\versions\3.9.6\lib\site-packages\websocket\_http.py", line 130, in connect
    sock = _open_socket(addrinfo_list, options.sockopt, options.timeout)
  File "C:\Users\shuitt\.pyenv\pyenv-win\versions\3.9.6\lib\site-packages\websocket\_http.py", line 205, in _open_socket
    raise err
  File "C:\Users\shuitt\.pyenv\pyenv-win\versions\3.9.6\lib\site-packages\websocket\_http.py", line 185, in _open_socket
    sock.connect(address)
ConnectionRefusedError: [WinError 10061] 対象のコンピューターによって拒否されたため、接続できませんでした。
 (main.py)
[ERROR] 2022-08-26 16:55:02,765 - Traceback (most recent call last):
  File "C:\Users\shuitt\.pyenv\pyenv-win\versions\3.9.6\lib\site-packages\websocket\_app.py", line 327, in run_forever
    self.sock.connect(
  File "C:\Users\shuitt\.pyenv\pyenv-win\versions\3.9.6\lib\site-packages\websocket\_core.py", line 244, in connect
    self.sock, addrs = connect(url, self.sock_opt, proxy_info(**options),
  File "C:\Users\shuitt\.pyenv\pyenv-win\versions\3.9.6\lib\site-packages\websocket\_http.py", line 130, in connect
    sock = _open_socket(addrinfo_list, options.sockopt, options.timeout)
  File "C:\Users\shuitt\.pyenv\pyenv-win\versions\3.9.6\lib\site-packages\websocket\_http.py", line 205, in _open_socket
    raise err
  File "C:\Users\shuitt\.pyenv\pyenv-win\versions\3.9.6\lib\site-packages\websocket\_http.py", line 185, in _open_socket
    sock.connect(address)
ConnectionRefusedError: [WinError 10061] 対象のコンピューターによって拒否されたため、接続できませんでした。
 (main.py)
[ERROR] 2022-08-26 16:55:07,053 - Traceback (most recent call last):
  File "C:\Users\shuitt\.pyenv\pyenv-win\versions\3.9.6\lib\site-packages\websocket\_app.py", line 327, in run_forever
    self.sock.connect(
  File "C:\Users\shuitt\.pyenv\pyenv-win\versions\3.9.6\lib\site-packages\websocket\_core.py", line 244, in connect
    self.sock, addrs = connect(url, self.sock_opt, proxy_info(**options),
  File "C:\Users\shuitt\.pyenv\pyenv-win\versions\3.9.6\lib\site-packages\websocket\_http.py", line 130, in connect
    sock = _open_socket(addrinfo_list, options.sockopt, options.timeout)
  File "C:\Users\shuitt\.pyenv\pyenv-win\versions\3.9.6\lib\site-packages\websocket\_http.py", line 205, in _open_socket
    raise err
  File "C:\Users\shuitt\.pyenv\pyenv-win\versions\3.9.6\lib\site-packages\websocket\_http.py", line 185, in _open_socket
    sock.connect(address)
ConnectionRefusedError: [WinError 10061] 対象のコンピューターによって拒否されたため、接続できませんでした。
 (main.py)
[ERROR] 2022-08-26 16:55:11,303 - Traceback (most recent call last):
  File "C:\Users\shuitt\.pyenv\pyenv-win\versions\3.9.6\lib\site-packages\websocket\_app.py", line 327, in run_forever
    self.sock.connect(
  File "C:\Users\shuitt\.pyenv\pyenv-win\versions\3.9.6\lib\site-packages\websocket\_core.py", line 244, in connect
    self.sock, addrs = connect(url, self.sock_opt, proxy_info(**options),
  File "C:\Users\shuitt\.pyenv\pyenv-win\versions\3.9.6\lib\site-packages\websocket\_http.py", line 130, in connect
    sock = _open_socket(addrinfo_list, options.sockopt, options.timeout)
  File "C:\Users\shuitt\.pyenv\pyenv-win\versions\3.9.6\lib\site-packages\websocket\_http.py", line 205, in _open_socket
    raise err
  File "C:\Users\shuitt\.pyenv\pyenv-win\versions\3.9.6\lib\site-packages\websocket\_http.py", line 185, in _open_socket
    sock.connect(address)
ConnectionRefusedError: [WinError 10061] 対象のコンピューターによって拒否されたため、接続できませんでした。
 (main.py)
[ERROR] 2022-08-26 16:55:13,978 - Traceback (most recent call last):
  File "C:\Users\shuitt\.pyenv\pyenv-win\versions\3.9.6\lib\site-packages\websocket\_app.py", line 424, in _callback
    callback(self, *args)
  File "c:\Users\shuitt\ドキュメント\programing\web\share\user\main.py", line 34, in on_open
    str({"user":user, "func": "new", deta: {"password": password}})
TypeError: unhashable type: 'dict'
 (main.py)
[ERROR] 2022-08-26 16:55:16,173 - Traceback (most recent call last):
  File "C:\Users\shuitt\.pyenv\pyenv-win\versions\3.9.6\lib\site-packages\websocket\_app.py", line 424, in _callback
    callback(self, *args)
  File "c:\Users\shuitt\ドキュメント\programing\web\share\user\main.py", line 34, in on_open
    str({"user":user, "func": "new", deta: {"password": password}})
TypeError: unhashable type: 'dict'
 (main.py)
[ERROR] 2022-08-26 16:55:18,376 - Traceback (most recent call last):
  File "C:\Users\shuitt\.pyenv\pyenv-win\versions\3.9.6\lib\site-packages\websocket\_app.py", line 424, in _callback
    callback(self, *args)
  File "c:\Users\shuitt\ドキュメント\programing\web\share\user\main.py", line 34, in on_open
    str({"user":user, "func": "new", deta: {"password": password}})
TypeError: unhashable type: 'dict'
 (main.py)
[ERROR] 2022-08-26 16:55:20,535 - Traceback (most recent call last):
  File "C:\Users\shuitt\.pyenv\pyenv-win\versions\3.9.6\lib\site-packages\websocket\_app.py", line 424, in _callback
    callback(self, *args)
  File "c:\Users\shuitt\ドキュメント\programing\web\share\user\main.py", line 34, in on_open
    str({"user":user, "func": "new", deta: {"password": password}})
TypeError: unhashable type: 'dict'
 (main.py)
[ERROR] 2022-08-26 16:55:22,699 - Traceback (most recent call last):
  File "C:\Users\shuitt\.pyenv\pyenv-win\versions\3.9.6\lib\site-packages\websocket\_app.py", line 424, in _callback
    callback(self, *args)
  File "c:\Users\shuitt\ドキュメント\programing\web\share\user\main.py", line 34, in on_open
    str({"user":user, "func": "new", deta: {"password": password}})
TypeError: unhashable type: 'dict'
 (main.py)
[ERROR] 2022-08-26 16:55:24,849 - Traceback (most recent call last):
  File "C:\Users\shuitt\.pyenv\pyenv-win\versions\3.9.6\lib\site-packages\websocket\_app.py", line 424, in _callback
    callback(self, *args)
  File "c:\Users\shuitt\ドキュメント\programing\web\share\user\main.py", line 34, in on_open
    str({"user":user, "func": "new", deta: {"password": password}})
TypeError: unhashable type: 'dict'
 (main.py)
[ERROR] 2022-08-26 16:55:27,004 - Traceback (most recent call last):
  File "C:\Users\shuitt\.pyenv\pyenv-win\versions\3.9.6\lib\site-packages\websocket\_app.py", line 424, in _callback
    callback(self, *args)
  File "c:\Users\shuitt\ドキュメント\programing\web\share\user\main.py", line 34, in on_open
    str({"user":user, "func": "new", deta: {"password": password}})
TypeError: unhashable type: 'dict'
 (main.py)
[ERROR] 2022-08-26 16:55:29,204 - Traceback (most recent call last):
  File "C:\Users\shuitt\.pyenv\pyenv-win\versions\3.9.6\lib\site-packages\websocket\_app.py", line 424, in _callback
    callback(self, *args)
  File "c:\Users\shuitt\ドキュメント\programing\web\share\user\main.py", line 34, in on_open
    str({"user":user, "func": "new", deta: {"password": password}})
TypeError: unhashable type: 'dict'
 (main.py)
[ERROR] 2022-08-26 16:55:31,358 - Traceback (most recent call last):
  File "C:\Users\shuitt\.pyenv\pyenv-win\versions\3.9.6\lib\site-packages\websocket\_app.py", line 424, in _callback
    callback(self, *args)
  File "c:\Users\shuitt\ドキュメント\programing\web\share\user\main.py", line 34, in on_open
    str({"user":user, "func": "new", deta: {"password": password}})
TypeError: unhashable type: 'dict'
 (main.py)
[ERROR] 2022-08-26 16:55:33,507 - Traceback (most recent call last):
  File "C:\Users\shuitt\.pyenv\pyenv-win\versions\3.9.6\lib\site-packages\websocket\_app.py", line 424, in _callback
    callback(self, *args)
  File "c:\Users\shuitt\ドキュメント\programing\web\share\user\main.py", line 34, in on_open
    str({"user":user, "func": "new", deta: {"password": password}})
TypeError: unhashable type: 'dict'
 (main.py)
[ERROR] 2022-08-26 16:55:35,655 - Traceback (most recent call last):
  File "C:\Users\shuitt\.pyenv\pyenv-win\versions\3.9.6\lib\site-packages\websocket\_app.py", line 424, in _callback
    callback(self, *args)
  File "c:\Users\shuitt\ドキュメント\programing\web\share\user\main.py", line 34, in on_open
    str({"user":user, "func": "new", deta: {"password": password}})
TypeError: unhashable type: 'dict'
 (main.py)
[ERROR] 2022-08-26 16:55:37,847 - Traceback (most recent call last):
  File "C:\Users\shuitt\.pyenv\pyenv-win\versions\3.9.6\lib\site-packages\websocket\_app.py", line 424, in _callback
    callback(self, *args)
  File "c:\Users\shuitt\ドキュメント\programing\web\share\user\main.py", line 34, in on_open
    str({"user":user, "func": "new", deta: {"password": password}})
TypeError: unhashable type: 'dict'
 (main.py)
[ERROR] 2022-08-26 16:55:40,018 - Traceback (most recent call last):
  File "C:\Users\shuitt\.pyenv\pyenv-win\versions\3.9.6\lib\site-packages\websocket\_app.py", line 424, in _callback
    callback(self, *args)
  File "c:\Users\shuitt\ドキュメント\programing\web\share\user\main.py", line 34, in on_open
    str({"user":user, "func": "new", deta: {"password": password}})
TypeError: unhashable type: 'dict'
 (main.py)
[ERROR] 2022-08-26 16:58:13,379 - Traceback (most recent call last):
  File "C:\Users\shuitt\.pyenv\pyenv-win\versions\3.9.6\lib\site-packages\websocket\_app.py", line 424, in _callback
    callback(self, *args)
  File "c:\Users\shuitt\ドキュメント\programing\web\share\user\main.py", line 36, in on_open
    with open("deta", "rb") as f:
FileNotFoundError: [Errno 2] No such file or directory: 'deta'
 (main.py)
[ERROR] 2022-08-26 16:58:15,559 - Traceback (most recent call last):
  File "C:\Users\shuitt\.pyenv\pyenv-win\versions\3.9.6\lib\site-packages\websocket\_app.py", line 424, in _callback
    callback(self, *args)
  File "c:\Users\shuitt\ドキュメント\programing\web\share\user\main.py", line 36, in on_open
    with open("deta", "rb") as f:
FileNotFoundError: [Errno 2] No such file or directory: 'deta'
 (main.py)
[ERROR] 2022-08-26 16:58:17,695 - Traceback (most recent call last):
  File "C:\Users\shuitt\.pyenv\pyenv-win\versions\3.9.6\lib\site-packages\websocket\_app.py", line 424, in _callback
    callback(self, *args)
  File "c:\Users\shuitt\ドキュメント\programing\web\share\user\main.py", line 36, in on_open
    with open("deta", "rb") as f:
FileNotFoundError: [Errno 2] No such file or directory: 'deta'
 (main.py)
[ERROR] 2022-08-26 16:58:19,886 - Traceback (most recent call last):
  File "C:\Users\shuitt\.pyenv\pyenv-win\versions\3.9.6\lib\site-packages\websocket\_app.py", line 424, in _callback
    callback(self, *args)
  File "c:\Users\shuitt\ドキュメント\programing\web\share\user\main.py", line 36, in on_open
    with open("deta", "rb") as f:
FileNotFoundError: [Errno 2] No such file or directory: 'deta'
 (main.py)
[ERROR] 2022-08-26 16:58:22,075 - Traceback (most recent call last):
  File "C:\Users\shuitt\.pyenv\pyenv-win\versions\3.9.6\lib\site-packages\websocket\_app.py", line 424, in _callback
    callback(self, *args)
  File "c:\Users\shuitt\ドキュメント\programing\web\share\user\main.py", line 36, in on_open
    with open("deta", "rb") as f:
FileNotFoundError: [Errno 2] No such file or directory: 'deta'
 (main.py)
[ERROR] 2022-08-26 16:58:24,220 - Traceback (most recent call last):
  File "C:\Users\shuitt\.pyenv\pyenv-win\versions\3.9.6\lib\site-packages\websocket\_app.py", line 424, in _callback
    callback(self, *args)
  File "c:\Users\shuitt\ドキュメント\programing\web\share\user\main.py", line 36, in on_open
    with open("deta", "rb") as f:
FileNotFoundError: [Errno 2] No such file or directory: 'deta'
 (main.py)
[ERROR] 2022-08-26 16:58:26,422 - Traceback (most recent call last):
  File "C:\Users\shuitt\.pyenv\pyenv-win\versions\3.9.6\lib\site-packages\websocket\_app.py", line 424, in _callback
    callback(self, *args)
  File "c:\Users\shuitt\ドキュメント\programing\web\share\user\main.py", line 36, in on_open
    with open("deta", "rb") as f:
FileNotFoundError: [Errno 2] No such file or directory: 'deta'
 (main.py)
[ERROR] 2022-08-26 16:58:28,587 - Traceback (most recent call last):
  File "C:\Users\shuitt\.pyenv\pyenv-win\versions\3.9.6\lib\site-packages\websocket\_app.py", line 424, in _callback
    callback(self, *args)
  File "c:\Users\shuitt\ドキュメント\programing\web\share\user\main.py", line 36, in on_open
    with open("deta", "rb") as f:
FileNotFoundError: [Errno 2] No such file or directory: 'deta'
 (main.py)
[ERROR] 2022-08-26 16:58:30,784 - Traceback (most recent call last):
  File "C:\Users\shuitt\.pyenv\pyenv-win\versions\3.9.6\lib\site-packages\websocket\_app.py", line 424, in _callback
    callback(self, *args)
  File "c:\Users\shuitt\ドキュメント\programing\web\share\user\main.py", line 36, in on_open
    with open("deta", "rb") as f:
FileNotFoundError: [Errno 2] No such file or directory: 'deta'
 (main.py)
[ERROR] 2022-08-26 16:58:32,934 - Traceback (most recent call last):
  File "C:\Users\shuitt\.pyenv\pyenv-win\versions\3.9.6\lib\site-packages\websocket\_app.py", line 424, in _callback
    callback(self, *args)
  File "c:\Users\shuitt\ドキュメント\programing\web\share\user\main.py", line 36, in on_open
    with open("deta", "rb") as f:
FileNotFoundError: [Errno 2] No such file or directory: 'deta'
 (main.py)
[ERROR] 2022-08-26 16:58:39,199 - Traceback (most recent call last):
  File "C:\Users\shuitt\.pyenv\pyenv-win\versions\3.9.6\lib\site-packages\websocket\_app.py", line 424, in _callback
    callback(self, *args)
  File "c:\Users\shuitt\ドキュメント\programing\web\share\user\main.py", line 36, in on_open
    with open("deta", "rb") as f:
FileNotFoundError: [Errno 2] No such file or directory: 'deta'
 (main.py)
[ERROR] 2022-08-26 16:58:41,349 - Traceback (most recent call last):
  File "C:\Users\shuitt\.pyenv\pyenv-win\versions\3.9.6\lib\site-packages\websocket\_app.py", line 424, in _callback
    callback(self, *args)
  File "c:\Users\shuitt\ドキュメント\programing\web\share\user\main.py", line 36, in on_open
    with open("deta", "rb") as f:
FileNotFoundError: [Errno 2] No such file or directory: 'deta'
 (main.py)
[ERROR] 2022-08-26 16:58:43,488 - Traceback (most recent call last):
  File "C:\Users\shuitt\.pyenv\pyenv-win\versions\3.9.6\lib\site-packages\websocket\_app.py", line 424, in _callback
    callback(self, *args)
  File "c:\Users\shuitt\ドキュメント\programing\web\share\user\main.py", line 36, in on_open
    with open("deta", "rb") as f:
FileNotFoundError: [Errno 2] No such file or directory: 'deta'
 (main.py)
[ERROR] 2022-08-26 16:58:45,656 - Traceback (most recent call last):
  File "C:\Users\shuitt\.pyenv\pyenv-win\versions\3.9.6\lib\site-packages\websocket\_app.py", line 424, in _callback
    callback(self, *args)
  File "c:\Users\shuitt\ドキュメント\programing\web\share\user\main.py", line 36, in on_open
    with open("deta", "rb") as f:
FileNotFoundError: [Errno 2] No such file or directory: 'deta'
 (main.py)
[ERROR] 2022-08-26 16:58:47,791 - Traceback (most recent call last):
  File "C:\Users\shuitt\.pyenv\pyenv-win\versions\3.9.6\lib\site-packages\websocket\_app.py", line 424, in _callback
    callback(self, *args)
  File "c:\Users\shuitt\ドキュメント\programing\web\share\user\main.py", line 36, in on_open
    with open("deta", "rb") as f:
FileNotFoundError: [Errno 2] No such file or directory: 'deta'
 (main.py)
[ERROR] 2022-08-26 16:58:49,934 - Traceback (most recent call last):
  File "C:\Users\shuitt\.pyenv\pyenv-win\versions\3.9.6\lib\site-packages\websocket\_app.py", line 424, in _callback
    callback(self, *args)
  File "c:\Users\shuitt\ドキュメント\programing\web\share\user\main.py", line 36, in on_open
    with open("deta", "rb") as f:
FileNotFoundError: [Errno 2] No such file or directory: 'deta'
 (main.py)
[ERROR] 2022-08-26 16:58:52,081 - Traceback (most recent call last):
  File "C:\Users\shuitt\.pyenv\pyenv-win\versions\3.9.6\lib\site-packages\websocket\_app.py", line 424, in _callback
    callback(self, *args)
  File "c:\Users\shuitt\ドキュメント\programing\web\share\user\main.py", line 36, in on_open
    with open("deta", "rb") as f:
FileNotFoundError: [Errno 2] No such file or directory: 'deta'
 (main.py)
[ERROR] 2022-08-26 16:58:54,259 - Traceback (most recent call last):
  File "C:\Users\shuitt\.pyenv\pyenv-win\versions\3.9.6\lib\site-packages\websocket\_app.py", line 424, in _callback
    callback(self, *args)
  File "c:\Users\shuitt\ドキュメント\programing\web\share\user\main.py", line 36, in on_open
    with open("deta", "rb") as f:
FileNotFoundError: [Errno 2] No such file or directory: 'deta'
 (main.py)
[ERROR] 2022-08-26 16:58:56,419 - Traceback (most recent call last):
  File "C:\Users\shuitt\.pyenv\pyenv-win\versions\3.9.6\lib\site-packages\websocket\_app.py", line 424, in _callback
    callback(self, *args)
  File "c:\Users\shuitt\ドキュメント\programing\web\share\user\main.py", line 36, in on_open
    with open("deta", "rb") as f:
FileNotFoundError: [Errno 2] No such file or directory: 'deta'
 (main.py)
[ERROR] 2022-08-26 16:58:58,585 - Traceback (most recent call last):
  File "C:\Users\shuitt\.pyenv\pyenv-win\versions\3.9.6\lib\site-packages\websocket\_app.py", line 424, in _callback
    callback(self, *args)
  File "c:\Users\shuitt\ドキュメント\programing\web\share\user\main.py", line 36, in on_open
    with open("deta", "rb") as f:
FileNotFoundError: [Errno 2] No such file or directory: 'deta'
 (main.py)
[ERROR] 2022-08-26 16:59:00,794 - Traceback (most recent call last):
  File "C:\Users\shuitt\.pyenv\pyenv-win\versions\3.9.6\lib\site-packages\websocket\_app.py", line 424, in _callback
    callback(self, *args)
  File "c:\Users\shuitt\ドキュメント\programing\web\share\user\main.py", line 36, in on_open
    with open("deta", "rb") as f:
FileNotFoundError: [Errno 2] No such file or directory: 'deta'
 (main.py)
[ERROR] 2022-08-26 16:59:02,961 - Traceback (most recent call last):
  File "C:\Users\shuitt\.pyenv\pyenv-win\versions\3.9.6\lib\site-packages\websocket\_app.py", line 424, in _callback
    callback(self, *args)
  File "c:\Users\shuitt\ドキュメント\programing\web\share\user\main.py", line 36, in on_open
    with open("deta", "rb") as f:
FileNotFoundError: [Errno 2] No such file or directory: 'deta'
 (main.py)
[ERROR] 2022-08-26 16:59:05,113 - Traceback (most recent call last):
  File "C:\Users\shuitt\.pyenv\pyenv-win\versions\3.9.6\lib\site-packages\websocket\_app.py", line 424, in _callback
    callback(self, *args)
  File "c:\Users\shuitt\ドキュメント\programing\web\share\user\main.py", line 36, in on_open
    with open("deta", "rb") as f:
FileNotFoundError: [Errno 2] No such file or directory: 'deta'
 (main.py)
[ERROR] 2022-08-26 16:59:07,309 - Traceback (most recent call last):
  File "C:\Users\shuitt\.pyenv\pyenv-win\versions\3.9.6\lib\site-packages\websocket\_app.py", line 424, in _callback
    callback(self, *args)
  File "c:\Users\shuitt\ドキュメント\programing\web\share\user\main.py", line 36, in on_open
    with open("deta", "rb") as f:
FileNotFoundError: [Errno 2] No such file or directory: 'deta'
 (main.py)
[ERROR] 2022-08-26 16:59:09,454 - Traceback (most recent call last):
  File "C:\Users\shuitt\.pyenv\pyenv-win\versions\3.9.6\lib\site-packages\websocket\_app.py", line 424, in _callback
    callback(self, *args)
  File "c:\Users\shuitt\ドキュメント\programing\web\share\user\main.py", line 36, in on_open
    with open("deta", "rb") as f:
FileNotFoundError: [Errno 2] No such file or directory: 'deta'
 (main.py)
[ERROR] 2022-08-26 16:59:11,641 - Traceback (most recent call last):
  File "C:\Users\shuitt\.pyenv\pyenv-win\versions\3.9.6\lib\site-packages\websocket\_app.py", line 424, in _callback
    callback(self, *args)
  File "c:\Users\shuitt\ドキュメント\programing\web\share\user\main.py", line 36, in on_open
    with open("deta", "rb") as f:
FileNotFoundError: [Errno 2] No such file or directory: 'deta'
 (main.py)
[ERROR] 2022-08-26 16:59:13,819 - Traceback (most recent call last):
  File "C:\Users\shuitt\.pyenv\pyenv-win\versions\3.9.6\lib\site-packages\websocket\_app.py", line 424, in _callback
    callback(self, *args)
  File "c:\Users\shuitt\ドキュメント\programing\web\share\user\main.py", line 36, in on_open
    with open("deta", "rb") as f:
FileNotFoundError: [Errno 2] No such file or directory: 'deta'
 (main.py)
[ERROR] 2022-08-26 16:59:15,985 - Traceback (most recent call last):
  File "C:\Users\shuitt\.pyenv\pyenv-win\versions\3.9.6\lib\site-packages\websocket\_app.py", line 424, in _callback
    callback(self, *args)
  File "c:\Users\shuitt\ドキュメント\programing\web\share\user\main.py", line 36, in on_open
    with open("deta", "rb") as f:
FileNotFoundError: [Errno 2] No such file or directory: 'deta'
 (main.py)
[ERROR] 2022-08-26 16:59:18,157 - Traceback (most recent call last):
  File "C:\Users\shuitt\.pyenv\pyenv-win\versions\3.9.6\lib\site-packages\websocket\_app.py", line 424, in _callback
    callback(self, *args)
  File "c:\Users\shuitt\ドキュメント\programing\web\share\user\main.py", line 36, in on_open
    with open("deta", "rb") as f:
FileNotFoundError: [Errno 2] No such file or directory: 'deta'
 (main.py)
[ERROR] 2022-08-26 16:59:20,352 - Traceback (most recent call last):
  File "C:\Users\shuitt\.pyenv\pyenv-win\versions\3.9.6\lib\site-packages\websocket\_app.py", line 424, in _callback
    callback(self, *args)
  File "c:\Users\shuitt\ドキュメント\programing\web\share\user\main.py", line 36, in on_open
    with open("deta", "rb") as f:
FileNotFoundError: [Errno 2] No such file or directory: 'deta'
 (main.py)
[ERROR] 2022-08-26 16:59:22,540 - Traceback (most recent call last):
  File "C:\Users\shuitt\.pyenv\pyenv-win\versions\3.9.6\lib\site-packages\websocket\_app.py", line 424, in _callback
    callback(self, *args)
  File "c:\Users\shuitt\ドキュメント\programing\web\share\user\main.py", line 36, in on_open
    with open("deta", "rb") as f:
FileNotFoundError: [Errno 2] No such file or directory: 'deta'
 (main.py)
[ERROR] 2022-08-26 16:59:24,697 - Traceback (most recent call last):
  File "C:\Users\shuitt\.pyenv\pyenv-win\versions\3.9.6\lib\site-packages\websocket\_app.py", line 424, in _callback
    callback(self, *args)
  File "c:\Users\shuitt\ドキュメント\programing\web\share\user\main.py", line 36, in on_open
    with open("deta", "rb") as f:
FileNotFoundError: [Errno 2] No such file or directory: 'deta'
 (main.py)
[ERROR] 2022-08-26 16:59:26,859 - Traceback (most recent call last):
  File "C:\Users\shuitt\.pyenv\pyenv-win\versions\3.9.6\lib\site-packages\websocket\_app.py", line 424, in _callback
    callback(self, *args)
  File "c:\Users\shuitt\ドキュメント\programing\web\share\user\main.py", line 36, in on_open
    with open("user/deta", "rb") as f:
FileNotFoundError: [Errno 2] No such file or directory: 'deta'
 (main.py)
[ERROR] 2022-08-26 16:59:29,051 - Traceback (most recent call last):
  File "C:\Users\shuitt\.pyenv\pyenv-win\versions\3.9.6\lib\site-packages\websocket\_app.py", line 424, in _callback
    callback(self, *args)
  File "c:\Users\shuitt\ドキュメント\programing\web\share\user\main.py", line 38, in on_open
    ws.send_binary(a)
AttributeError: 'WebSocketApp' object has no attribute 'send_binary'
 (main.py)
[ERROR] 2022-08-26 16:59:31,190 - Traceback (most recent call last):
  File "C:\Users\shuitt\.pyenv\pyenv-win\versions\3.9.6\lib\site-packages\websocket\_app.py", line 424, in _callback
    callback(self, *args)
  File "c:\Users\shuitt\ドキュメント\programing\web\share\user\main.py", line 38, in on_open
    ws.send_binary(a)
AttributeError: 'WebSocketApp' object has no attribute 'send_binary'
 (main.py)
[ERROR] 2022-08-26 16:59:33,329 - Traceback (most recent call last):
  File "C:\Users\shuitt\.pyenv\pyenv-win\versions\3.9.6\lib\site-packages\websocket\_app.py", line 424, in _callback
    callback(self, *args)
  File "c:\Users\shuitt\ドキュメント\programing\web\share\user\main.py", line 38, in on_open
    ws.send_binary(a)
AttributeError: 'WebSocketApp' object has no attribute 'send_binary'
 (main.py)
[ERROR] 2022-08-26 16:59:59,426 - Traceback (most recent call last):
  File "C:\Users\shuitt\.pyenv\pyenv-win\versions\3.9.6\lib\site-packages\websocket\_app.py", line 424, in _callback
    callback(self, *args)
  File "c:\Users\shuitt\ドキュメント\programing\web\share\user\main.py", line 38, in on_open
    ws.send_binary(a)
AttributeError: 'WebSocketApp' object has no attribute 'send_binary'
 (main.py)
[ERROR] 2022-08-26 17:00:01,625 - Traceback (most recent call last):
  File "C:\Users\shuitt\.pyenv\pyenv-win\versions\3.9.6\lib\site-packages\websocket\_app.py", line 424, in _callback
    callback(self, *args)
  File "c:\Users\shuitt\ドキュメント\programing\web\share\user\main.py", line 38, in on_open
    ws.send_binary(a)
AttributeError: 'WebSocketApp' object has no attribute 'send_binary'
 (main.py)
[ERROR] 2022-08-26 17:00:03,760 - Traceback (most recent call last):
  File "C:\Users\shuitt\.pyenv\pyenv-win\versions\3.9.6\lib\site-packages\websocket\_app.py", line 424, in _callback
    callback(self, *args)
  File "c:\Users\shuitt\ドキュメント\programing\web\share\user\main.py", line 38, in on_open
    ws.send_binary(a)
AttributeError: 'WebSocketApp' object has no attribute 'send_binary'
 (main.py)
[ERROR] 2022-08-26 17:00:05,930 - Traceback (most recent call last):
  File "C:\Users\shuitt\.pyenv\pyenv-win\versions\3.9.6\lib\site-packages\websocket\_app.py", line 424, in _callback
    callback(self, *args)
  File "c:\Users\shuitt\ドキュメント\programing\web\share\user\main.py", line 38, in on_open
    ws.send_binary(a)
AttributeError: 'WebSocketApp' object has no attribute 'send_binary'
 (main.py)
[ERROR] 2022-08-26 17:00:08,092 - Traceback (most recent call last):
  File "C:\Users\shuitt\.pyenv\pyenv-win\versions\3.9.6\lib\site-packages\websocket\_app.py", line 424, in _callback
    callback(self, *args)
  File "c:\Users\shuitt\ドキュメント\programing\web\share\user\main.py", line 38, in on_open
    ws.send_binary(a)
AttributeError: 'WebSocketApp' object has no attribute 'send_binary'
 (main.py)
[ERROR] 2022-08-26 17:00:10,292 - Traceback (most recent call last):
  File "C:\Users\shuitt\.pyenv\pyenv-win\versions\3.9.6\lib\site-packages\websocket\_app.py", line 424, in _callback
    callback(self, *args)
  File "c:\Users\shuitt\ドキュメント\programing\web\share\user\main.py", line 38, in on_open
    ws.send_binary(a)
AttributeError: 'WebSocketApp' object has no attribute 'send_binary'
 (main.py)
[ERROR] 2022-08-26 17:00:24,298 - Traceback (most recent call last):
  File "C:\Users\shuitt\.pyenv\pyenv-win\versions\3.9.6\lib\site-packages\websocket\_app.py", line 383, in run_forever
    dispatcher.read(self.sock.sock, read, check)
  File "C:\Users\shuitt\.pyenv\pyenv-win\versions\3.9.6\lib\site-packages\websocket\_app.py", line 48, in read
    if not read_callback():
  File "C:\Users\shuitt\.pyenv\pyenv-win\versions\3.9.6\lib\site-packages\websocket\_app.py", line 349, in read
    op_code, frame = self.sock.recv_data_frame(True)
  File "C:\Users\shuitt\.pyenv\pyenv-win\versions\3.9.6\lib\site-packages\websocket\_core.py", line 401, in recv_data_frame
    frame = self.recv_frame()
  File "C:\Users\shuitt\.pyenv\pyenv-win\versions\3.9.6\lib\site-packages\websocket\_core.py", line 440, in recv_frame
    return self.frame_buffer.recv_frame()
  File "C:\Users\shuitt\.pyenv\pyenv-win\versions\3.9.6\lib\site-packages\websocket\_abnf.py", line 338, in recv_frame
    self.recv_header()
  File "C:\Users\shuitt\.pyenv\pyenv-win\versions\3.9.6\lib\site-packages\websocket\_abnf.py", line 294, in recv_header
    header = self.recv_strict(2)
  File "C:\Users\shuitt\.pyenv\pyenv-win\versions\3.9.6\lib\site-packages\websocket\_abnf.py", line 373, in recv_strict
    bytes_ = self.recv(min(16384, shortage))
  File "C:\Users\shuitt\.pyenv\pyenv-win\versions\3.9.6\lib\site-packages\websocket\_core.py", line 524, in _recv
    return recv(self.sock, bufsize)
  File "C:\Users\shuitt\.pyenv\pyenv-win\versions\3.9.6\lib\site-packages\websocket\_socket.py", line 122, in recv
    raise WebSocketConnectionClosedException(
websocket._exceptions.WebSocketConnectionClosedException: Connection to remote host was lost.
 (main.py)
[ERROR] 2022-08-26 17:00:26,448 - Traceback (most recent call last):
  File "C:\Users\shuitt\.pyenv\pyenv-win\versions\3.9.6\lib\site-packages\websocket\_app.py", line 383, in run_forever
    dispatcher.read(self.sock.sock, read, check)
  File "C:\Users\shuitt\.pyenv\pyenv-win\versions\3.9.6\lib\site-packages\websocket\_app.py", line 48, in read
    if not read_callback():
  File "C:\Users\shuitt\.pyenv\pyenv-win\versions\3.9.6\lib\site-packages\websocket\_app.py", line 349, in read
    op_code, frame = self.sock.recv_data_frame(True)
  File "C:\Users\shuitt\.pyenv\pyenv-win\versions\3.9.6\lib\site-packages\websocket\_core.py", line 401, in recv_data_frame
    frame = self.recv_frame()
  File "C:\Users\shuitt\.pyenv\pyenv-win\versions\3.9.6\lib\site-packages\websocket\_core.py", line 440, in recv_frame
    return self.frame_buffer.recv_frame()
  File "C:\Users\shuitt\.pyenv\pyenv-win\versions\3.9.6\lib\site-packages\websocket\_abnf.py", line 338, in recv_frame
    self.recv_header()
  File "C:\Users\shuitt\.pyenv\pyenv-win\versions\3.9.6\lib\site-packages\websocket\_abnf.py", line 294, in recv_header
    header = self.recv_strict(2)
  File "C:\Users\shuitt\.pyenv\pyenv-win\versions\3.9.6\lib\site-packages\websocket\_abnf.py", line 373, in recv_strict
    bytes_ = self.recv(min(16384, shortage))
  File "C:\Users\shuitt\.pyenv\pyenv-win\versions\3.9.6\lib\site-packages\websocket\_core.py", line 524, in _recv
    return recv(self.sock, bufsize)
  File "C:\Users\shuitt\.pyenv\pyenv-win\versions\3.9.6\lib\site-packages\websocket\_socket.py", line 122, in recv
    raise WebSocketConnectionClosedException(
websocket._exceptions.WebSocketConnectionClosedException: Connection to remote host was lost.
 (main.py)
[ERROR] 2022-08-26 17:00:28,607 - Traceback (most recent call last):
  File "C:\Users\shuitt\.pyenv\pyenv-win\versions\3.9.6\lib\site-packages\websocket\_app.py", line 383, in run_forever
    dispatcher.read(self.sock.sock, read, check)
  File "C:\Users\shuitt\.pyenv\pyenv-win\versions\3.9.6\lib\site-packages\websocket\_app.py", line 48, in read
    if not read_callback():
  File "C:\Users\shuitt\.pyenv\pyenv-win\versions\3.9.6\lib\site-packages\websocket\_app.py", line 349, in read
    op_code, frame = self.sock.recv_data_frame(True)
  File "C:\Users\shuitt\.pyenv\pyenv-win\versions\3.9.6\lib\site-packages\websocket\_core.py", line 401, in recv_data_frame
    frame = self.recv_frame()
  File "C:\Users\shuitt\.pyenv\pyenv-win\versions\3.9.6\lib\site-packages\websocket\_core.py", line 440, in recv_frame
    return self.frame_buffer.recv_frame()
  File "C:\Users\shuitt\.pyenv\pyenv-win\versions\3.9.6\lib\site-packages\websocket\_abnf.py", line 338, in recv_frame
    self.recv_header()
  File "C:\Users\shuitt\.pyenv\pyenv-win\versions\3.9.6\lib\site-packages\websocket\_abnf.py", line 294, in recv_header
    header = self.recv_strict(2)
  File "C:\Users\shuitt\.pyenv\pyenv-win\versions\3.9.6\lib\site-packages\websocket\_abnf.py", line 373, in recv_strict
    bytes_ = self.recv(min(16384, shortage))
  File "C:\Users\shuitt\.pyenv\pyenv-win\versions\3.9.6\lib\site-packages\websocket\_core.py", line 524, in _recv
    return recv(self.sock, bufsize)
  File "C:\Users\shuitt\.pyenv\pyenv-win\versions\3.9.6\lib\site-packages\websocket\_socket.py", line 122, in recv
    raise WebSocketConnectionClosedException(
websocket._exceptions.WebSocketConnectionClosedException: Connection to remote host was lost.
 (main.py)
[ERROR] 2022-08-26 17:00:30,771 - Traceback (most recent call last):
  File "C:\Users\shuitt\.pyenv\pyenv-win\versions\3.9.6\lib\site-packages\websocket\_app.py", line 383, in run_forever
    dispatcher.read(self.sock.sock, read, check)
  File "C:\Users\shuitt\.pyenv\pyenv-win\versions\3.9.6\lib\site-packages\websocket\_app.py", line 48, in read
    if not read_callback():
  File "C:\Users\shuitt\.pyenv\pyenv-win\versions\3.9.6\lib\site-packages\websocket\_app.py", line 349, in read
    op_code, frame = self.sock.recv_data_frame(True)
  File "C:\Users\shuitt\.pyenv\pyenv-win\versions\3.9.6\lib\site-packages\websocket\_core.py", line 401, in recv_data_frame
    frame = self.recv_frame()
  File "C:\Users\shuitt\.pyenv\pyenv-win\versions\3.9.6\lib\site-packages\websocket\_core.py", line 440, in recv_frame
    return self.frame_buffer.recv_frame()
  File "C:\Users\shuitt\.pyenv\pyenv-win\versions\3.9.6\lib\site-packages\websocket\_abnf.py", line 338, in recv_frame
    self.recv_header()
  File "C:\Users\shuitt\.pyenv\pyenv-win\versions\3.9.6\lib\site-packages\websocket\_abnf.py", line 294, in recv_header
    header = self.recv_strict(2)
  File "C:\Users\shuitt\.pyenv\pyenv-win\versions\3.9.6\lib\site-packages\websocket\_abnf.py", line 373, in recv_strict
    bytes_ = self.recv(min(16384, shortage))
  File "C:\Users\shuitt\.pyenv\pyenv-win\versions\3.9.6\lib\site-packages\websocket\_core.py", line 524, in _recv
    return recv(self.sock, bufsize)
  File "C:\Users\shuitt\.pyenv\pyenv-win\versions\3.9.6\lib\site-packages\websocket\_socket.py", line 122, in recv
    raise WebSocketConnectionClosedException(
websocket._exceptions.WebSocketConnectionClosedException: Connection to remote host was lost.
 (main.py)
[ERROR] 2022-08-26 17:00:32,937 - Traceback (most recent call last):
  File "C:\Users\shuitt\.pyenv\pyenv-win\versions\3.9.6\lib\site-packages\websocket\_app.py", line 383, in run_forever
    dispatcher.read(self.sock.sock, read, check)
  File "C:\Users\shuitt\.pyenv\pyenv-win\versions\3.9.6\lib\site-packages\websocket\_app.py", line 48, in read
    if not read_callback():
  File "C:\Users\shuitt\.pyenv\pyenv-win\versions\3.9.6\lib\site-packages\websocket\_app.py", line 349, in read
    op_code, frame = self.sock.recv_data_frame(True)
  File "C:\Users\shuitt\.pyenv\pyenv-win\versions\3.9.6\lib\site-packages\websocket\_core.py", line 401, in recv_data_frame
    frame = self.recv_frame()
  File "C:\Users\shuitt\.pyenv\pyenv-win\versions\3.9.6\lib\site-packages\websocket\_core.py", line 440, in recv_frame
    return self.frame_buffer.recv_frame()
  File "C:\Users\shuitt\.pyenv\pyenv-win\versions\3.9.6\lib\site-packages\websocket\_abnf.py", line 338, in recv_frame
    self.recv_header()
  File "C:\Users\shuitt\.pyenv\pyenv-win\versions\3.9.6\lib\site-packages\websocket\_abnf.py", line 294, in recv_header
    header = self.recv_strict(2)
  File "C:\Users\shuitt\.pyenv\pyenv-win\versions\3.9.6\lib\site-packages\websocket\_abnf.py", line 373, in recv_strict
    bytes_ = self.recv(min(16384, shortage))
  File "C:\Users\shuitt\.pyenv\pyenv-win\versions\3.9.6\lib\site-packages\websocket\_core.py", line 524, in _recv
    return recv(self.sock, bufsize)
  File "C:\Users\shuitt\.pyenv\pyenv-win\versions\3.9.6\lib\site-packages\websocket\_socket.py", line 122, in recv
    raise WebSocketConnectionClosedException(
websocket._exceptions.WebSocketConnectionClosedException: Connection to remote host was lost.
 (main.py)
[ERROR] 2022-08-26 17:00:35,095 - Traceback (most recent call last):
  File "C:\Users\shuitt\.pyenv\pyenv-win\versions\3.9.6\lib\site-packages\websocket\_app.py", line 383, in run_forever
    dispatcher.read(self.sock.sock, read, check)
  File "C:\Users\shuitt\.pyenv\pyenv-win\versions\3.9.6\lib\site-packages\websocket\_app.py", line 48, in read
    if not read_callback():
  File "C:\Users\shuitt\.pyenv\pyenv-win\versions\3.9.6\lib\site-packages\websocket\_app.py", line 349, in read
    op_code, frame = self.sock.recv_data_frame(True)
  File "C:\Users\shuitt\.pyenv\pyenv-win\versions\3.9.6\lib\site-packages\websocket\_core.py", line 401, in recv_data_frame
    frame = self.recv_frame()
  File "C:\Users\shuitt\.pyenv\pyenv-win\versions\3.9.6\lib\site-packages\websocket\_core.py", line 440, in recv_frame
    return self.frame_buffer.recv_frame()
  File "C:\Users\shuitt\.pyenv\pyenv-win\versions\3.9.6\lib\site-packages\websocket\_abnf.py", line 338, in recv_frame
    self.recv_header()
  File "C:\Users\shuitt\.pyenv\pyenv-win\versions\3.9.6\lib\site-packages\websocket\_abnf.py", line 294, in recv_header
    header = self.recv_strict(2)
  File "C:\Users\shuitt\.pyenv\pyenv-win\versions\3.9.6\lib\site-packages\websocket\_abnf.py", line 373, in recv_strict
    bytes_ = self.recv(min(16384, shortage))
  File "C:\Users\shuitt\.pyenv\pyenv-win\versions\3.9.6\lib\site-packages\websocket\_core.py", line 524, in _recv
    return recv(self.sock, bufsize)
  File "C:\Users\shuitt\.pyenv\pyenv-win\versions\3.9.6\lib\site-packages\websocket\_socket.py", line 122, in recv
    raise WebSocketConnectionClosedException(
websocket._exceptions.WebSocketConnectionClosedException: Connection to remote host was lost.
 (main.py)
[ERROR] 2022-08-26 17:00:37,258 - Traceback (most recent call last):
  File "C:\Users\shuitt\.pyenv\pyenv-win\versions\3.9.6\lib\site-packages\websocket\_app.py", line 383, in run_forever
    dispatcher.read(self.sock.sock, read, check)
  File "C:\Users\shuitt\.pyenv\pyenv-win\versions\3.9.6\lib\site-packages\websocket\_app.py", line 48, in read
    if not read_callback():
  File "C:\Users\shuitt\.pyenv\pyenv-win\versions\3.9.6\lib\site-packages\websocket\_app.py", line 349, in read
    op_code, frame = self.sock.recv_data_frame(True)
  File "C:\Users\shuitt\.pyenv\pyenv-win\versions\3.9.6\lib\site-packages\websocket\_core.py", line 401, in recv_data_frame
    frame = self.recv_frame()
  File "C:\Users\shuitt\.pyenv\pyenv-win\versions\3.9.6\lib\site-packages\websocket\_core.py", line 440, in recv_frame
    return self.frame_buffer.recv_frame()
  File "C:\Users\shuitt\.pyenv\pyenv-win\versions\3.9.6\lib\site-packages\websocket\_abnf.py", line 338, in recv_frame
    self.recv_header()
  File "C:\Users\shuitt\.pyenv\pyenv-win\versions\3.9.6\lib\site-packages\websocket\_abnf.py", line 294, in recv_header
    header = self.recv_strict(2)
  File "C:\Users\shuitt\.pyenv\pyenv-win\versions\3.9.6\lib\site-packages\websocket\_abnf.py", line 373, in recv_strict
    bytes_ = self.recv(min(16384, shortage))
  File "C:\Users\shuitt\.pyenv\pyenv-win\versions\3.9.6\lib\site-packages\websocket\_core.py", line 524, in _recv
    return recv(self.sock, bufsize)
  File "C:\Users\shuitt\.pyenv\pyenv-win\versions\3.9.6\lib\site-packages\websocket\_socket.py", line 122, in recv
    raise WebSocketConnectionClosedException(
websocket._exceptions.WebSocketConnectionClosedException: Connection to remote host was lost.
 (main.py)
[ERROR] 2022-08-26 17:00:39,419 - Traceback (most recent call last):
  File "C:\Users\shuitt\.pyenv\pyenv-win\versions\3.9.6\lib\site-packages\websocket\_app.py", line 383, in run_forever
    dispatcher.read(self.sock.sock, read, check)
  File "C:\Users\shuitt\.pyenv\pyenv-win\versions\3.9.6\lib\site-packages\websocket\_app.py", line 48, in read
    if not read_callback():
  File "C:\Users\shuitt\.pyenv\pyenv-win\versions\3.9.6\lib\site-packages\websocket\_app.py", line 349, in read
    op_code, frame = self.sock.recv_data_frame(True)
  File "C:\Users\shuitt\.pyenv\pyenv-win\versions\3.9.6\lib\site-packages\websocket\_core.py", line 401, in recv_data_frame
    frame = self.recv_frame()
  File "C:\Users\shuitt\.pyenv\pyenv-win\versions\3.9.6\lib\site-packages\websocket\_core.py", line 440, in recv_frame
    return self.frame_buffer.recv_frame()
  File "C:\Users\shuitt\.pyenv\pyenv-win\versions\3.9.6\lib\site-packages\websocket\_abnf.py", line 338, in recv_frame
    self.recv_header()
  File "C:\Users\shuitt\.pyenv\pyenv-win\versions\3.9.6\lib\site-packages\websocket\_abnf.py", line 294, in recv_header
    header = self.recv_strict(2)
  File "C:\Users\shuitt\.pyenv\pyenv-win\versions\3.9.6\lib\site-packages\websocket\_abnf.py", line 373, in recv_strict
    bytes_ = self.recv(min(16384, shortage))
  File "C:\Users\shuitt\.pyenv\pyenv-win\versions\3.9.6\lib\site-packages\websocket\_core.py", line 524, in _recv
    return recv(self.sock, bufsize)
  File "C:\Users\shuitt\.pyenv\pyenv-win\versions\3.9.6\lib\site-packages\websocket\_socket.py", line 122, in recv
    raise WebSocketConnectionClosedException(
websocket._exceptions.WebSocketConnectionClosedException: Connection to remote host was lost.
 (main.py)
[ERROR] 2022-08-26 17:00:41,578 - Traceback (most recent call last):
  File "C:\Users\shuitt\.pyenv\pyenv-win\versions\3.9.6\lib\site-packages\websocket\_app.py", line 383, in run_forever
    dispatcher.read(self.sock.sock, read, check)
  File "C:\Users\shuitt\.pyenv\pyenv-win\versions\3.9.6\lib\site-packages\websocket\_app.py", line 48, in read
    if not read_callback():
  File "C:\Users\shuitt\.pyenv\pyenv-win\versions\3.9.6\lib\site-packages\websocket\_app.py", line 349, in read
    op_code, frame = self.sock.recv_data_frame(True)
  File "C:\Users\shuitt\.pyenv\pyenv-win\versions\3.9.6\lib\site-packages\websocket\_core.py", line 401, in recv_data_frame
    frame = self.recv_frame()
  File "C:\Users\shuitt\.pyenv\pyenv-win\versions\3.9.6\lib\site-packages\websocket\_core.py", line 440, in recv_frame
    return self.frame_buffer.recv_frame()
  File "C:\Users\shuitt\.pyenv\pyenv-win\versions\3.9.6\lib\site-packages\websocket\_abnf.py", line 338, in recv_frame
    self.recv_header()
  File "C:\Users\shuitt\.pyenv\pyenv-win\versions\3.9.6\lib\site-packages\websocket\_abnf.py", line 294, in recv_header
    header = self.recv_strict(2)
  File "C:\Users\shuitt\.pyenv\pyenv-win\versions\3.9.6\lib\site-packages\websocket\_abnf.py", line 373, in recv_strict
    bytes_ = self.recv(min(16384, shortage))
  File "C:\Users\shuitt\.pyenv\pyenv-win\versions\3.9.6\lib\site-packages\websocket\_core.py", line 524, in _recv
    return recv(self.sock, bufsize)
  File "C:\Users\shuitt\.pyenv\pyenv-win\versions\3.9.6\lib\site-packages\websocket\_socket.py", line 122, in recv
    raise WebSocketConnectionClosedException(
websocket._exceptions.WebSocketConnectionClosedException: Connection to remote host was lost.
 (main.py)
[ERROR] 2022-08-26 17:00:43,753 - Traceback (most recent call last):
  File "C:\Users\shuitt\.pyenv\pyenv-win\versions\3.9.6\lib\site-packages\websocket\_app.py", line 383, in run_forever
    dispatcher.read(self.sock.sock, read, check)
  File "C:\Users\shuitt\.pyenv\pyenv-win\versions\3.9.6\lib\site-packages\websocket\_app.py", line 48, in read
    if not read_callback():
  File "C:\Users\shuitt\.pyenv\pyenv-win\versions\3.9.6\lib\site-packages\websocket\_app.py", line 349, in read
    op_code, frame = self.sock.recv_data_frame(True)
  File "C:\Users\shuitt\.pyenv\pyenv-win\versions\3.9.6\lib\site-packages\websocket\_core.py", line 401, in recv_data_frame
    frame = self.recv_frame()
  File "C:\Users\shuitt\.pyenv\pyenv-win\versions\3.9.6\lib\site-packages\websocket\_core.py", line 440, in recv_frame
    return self.frame_buffer.recv_frame()
  File "C:\Users\shuitt\.pyenv\pyenv-win\versions\3.9.6\lib\site-packages\websocket\_abnf.py", line 338, in recv_frame
    self.recv_header()
  File "C:\Users\shuitt\.pyenv\pyenv-win\versions\3.9.6\lib\site-packages\websocket\_abnf.py", line 294, in recv_header
    header = self.recv_strict(2)
  File "C:\Users\shuitt\.pyenv\pyenv-win\versions\3.9.6\lib\site-packages\websocket\_abnf.py", line 373, in recv_strict
    bytes_ = self.recv(min(16384, shortage))
  File "C:\Users\shuitt\.pyenv\pyenv-win\versions\3.9.6\lib\site-packages\websocket\_core.py", line 524, in _recv
    return recv(self.sock, bufsize)
  File "C:\Users\shuitt\.pyenv\pyenv-win\versions\3.9.6\lib\site-packages\websocket\_socket.py", line 122, in recv
    raise WebSocketConnectionClosedException(
websocket._exceptions.WebSocketConnectionClosedException: Connection to remote host was lost.
 (main.py)
[ERROR] 2022-08-26 17:00:45,924 - Traceback (most recent call last):
  File "C:\Users\shuitt\.pyenv\pyenv-win\versions\3.9.6\lib\site-packages\websocket\_app.py", line 383, in run_forever
    dispatcher.read(self.sock.sock, read, check)
  File "C:\Users\shuitt\.pyenv\pyenv-win\versions\3.9.6\lib\site-packages\websocket\_app.py", line 48, in read
    if not read_callback():
  File "C:\Users\shuitt\.pyenv\pyenv-win\versions\3.9.6\lib\site-packages\websocket\_app.py", line 349, in read
    op_code, frame = self.sock.recv_data_frame(True)
  File "C:\Users\shuitt\.pyenv\pyenv-win\versions\3.9.6\lib\site-packages\websocket\_core.py", line 401, in recv_data_frame
    frame = self.recv_frame()
  File "C:\Users\shuitt\.pyenv\pyenv-win\versions\3.9.6\lib\site-packages\websocket\_core.py", line 440, in recv_frame
    return self.frame_buffer.recv_frame()
  File "C:\Users\shuitt\.pyenv\pyenv-win\versions\3.9.6\lib\site-packages\websocket\_abnf.py", line 338, in recv_frame
    self.recv_header()
  File "C:\Users\shuitt\.pyenv\pyenv-win\versions\3.9.6\lib\site-packages\websocket\_abnf.py", line 294, in recv_header
    header = self.recv_strict(2)
  File "C:\Users\shuitt\.pyenv\pyenv-win\versions\3.9.6\lib\site-packages\websocket\_abnf.py", line 373, in recv_strict
    bytes_ = self.recv(min(16384, shortage))
  File "C:\Users\shuitt\.pyenv\pyenv-win\versions\3.9.6\lib\site-packages\websocket\_core.py", line 524, in _recv
    return recv(self.sock, bufsize)
  File "C:\Users\shuitt\.pyenv\pyenv-win\versions\3.9.6\lib\site-packages\websocket\_socket.py", line 122, in recv
    raise WebSocketConnectionClosedException(
websocket._exceptions.WebSocketConnectionClosedException: Connection to remote host was lost.
 (main.py)
[ERROR] 2022-08-26 17:00:48,123 - Traceback (most recent call last):
  File "C:\Users\shuitt\.pyenv\pyenv-win\versions\3.9.6\lib\site-packages\websocket\_app.py", line 383, in run_forever
    dispatcher.read(self.sock.sock, read, check)
  File "C:\Users\shuitt\.pyenv\pyenv-win\versions\3.9.6\lib\site-packages\websocket\_app.py", line 48, in read
    if not read_callback():
  File "C:\Users\shuitt\.pyenv\pyenv-win\versions\3.9.6\lib\site-packages\websocket\_app.py", line 349, in read
    op_code, frame = self.sock.recv_data_frame(True)
  File "C:\Users\shuitt\.pyenv\pyenv-win\versions\3.9.6\lib\site-packages\websocket\_core.py", line 401, in recv_data_frame
    frame = self.recv_frame()
  File "C:\Users\shuitt\.pyenv\pyenv-win\versions\3.9.6\lib\site-packages\websocket\_core.py", line 440, in recv_frame
    return self.frame_buffer.recv_frame()
  File "C:\Users\shuitt\.pyenv\pyenv-win\versions\3.9.6\lib\site-packages\websocket\_abnf.py", line 338, in recv_frame
    self.recv_header()
  File "C:\Users\shuitt\.pyenv\pyenv-win\versions\3.9.6\lib\site-packages\websocket\_abnf.py", line 294, in recv_header
    header = self.recv_strict(2)
  File "C:\Users\shuitt\.pyenv\pyenv-win\versions\3.9.6\lib\site-packages\websocket\_abnf.py", line 373, in recv_strict
    bytes_ = self.recv(min(16384, shortage))
  File "C:\Users\shuitt\.pyenv\pyenv-win\versions\3.9.6\lib\site-packages\websocket\_core.py", line 524, in _recv
    return recv(self.sock, bufsize)
  File "C:\Users\shuitt\.pyenv\pyenv-win\versions\3.9.6\lib\site-packages\websocket\_socket.py", line 122, in recv
    raise WebSocketConnectionClosedException(
websocket._exceptions.WebSocketConnectionClosedException: Connection to remote host was lost.
 (main.py)
[ERROR] 2022-08-26 17:00:50,306 - Traceback (most recent call last):
  File "C:\Users\shuitt\.pyenv\pyenv-win\versions\3.9.6\lib\site-packages\websocket\_app.py", line 383, in run_forever
    dispatcher.read(self.sock.sock, read, check)
  File "C:\Users\shuitt\.pyenv\pyenv-win\versions\3.9.6\lib\site-packages\websocket\_app.py", line 48, in read
    if not read_callback():
  File "C:\Users\shuitt\.pyenv\pyenv-win\versions\3.9.6\lib\site-packages\websocket\_app.py", line 349, in read
    op_code, frame = self.sock.recv_data_frame(True)
  File "C:\Users\shuitt\.pyenv\pyenv-win\versions\3.9.6\lib\site-packages\websocket\_core.py", line 401, in recv_data_frame
    frame = self.recv_frame()
  File "C:\Users\shuitt\.pyenv\pyenv-win\versions\3.9.6\lib\site-packages\websocket\_core.py", line 440, in recv_frame
    return self.frame_buffer.recv_frame()
  File "C:\Users\shuitt\.pyenv\pyenv-win\versions\3.9.6\lib\site-packages\websocket\_abnf.py", line 338, in recv_frame
    self.recv_header()
  File "C:\Users\shuitt\.pyenv\pyenv-win\versions\3.9.6\lib\site-packages\websocket\_abnf.py", line 294, in recv_header
    header = self.recv_strict(2)
  File "C:\Users\shuitt\.pyenv\pyenv-win\versions\3.9.6\lib\site-packages\websocket\_abnf.py", line 373, in recv_strict
    bytes_ = self.recv(min(16384, shortage))
  File "C:\Users\shuitt\.pyenv\pyenv-win\versions\3.9.6\lib\site-packages\websocket\_core.py", line 524, in _recv
    return recv(self.sock, bufsize)
  File "C:\Users\shuitt\.pyenv\pyenv-win\versions\3.9.6\lib\site-packages\websocket\_socket.py", line 122, in recv
    raise WebSocketConnectionClosedException(
websocket._exceptions.WebSocketConnectionClosedException: Connection to remote host was lost.
 (main.py)
[ERROR] 2022-08-26 17:00:52,479 - Traceback (most recent call last):
  File "C:\Users\shuitt\.pyenv\pyenv-win\versions\3.9.6\lib\site-packages\websocket\_app.py", line 383, in run_forever
    dispatcher.read(self.sock.sock, read, check)
  File "C:\Users\shuitt\.pyenv\pyenv-win\versions\3.9.6\lib\site-packages\websocket\_app.py", line 48, in read
    if not read_callback():
  File "C:\Users\shuitt\.pyenv\pyenv-win\versions\3.9.6\lib\site-packages\websocket\_app.py", line 349, in read
    op_code, frame = self.sock.recv_data_frame(True)
  File "C:\Users\shuitt\.pyenv\pyenv-win\versions\3.9.6\lib\site-packages\websocket\_core.py", line 401, in recv_data_frame
    frame = self.recv_frame()
  File "C:\Users\shuitt\.pyenv\pyenv-win\versions\3.9.6\lib\site-packages\websocket\_core.py", line 440, in recv_frame
    return self.frame_buffer.recv_frame()
  File "C:\Users\shuitt\.pyenv\pyenv-win\versions\3.9.6\lib\site-packages\websocket\_abnf.py", line 338, in recv_frame
    self.recv_header()
  File "C:\Users\shuitt\.pyenv\pyenv-win\versions\3.9.6\lib\site-packages\websocket\_abnf.py", line 294, in recv_header
    header = self.recv_strict(2)
  File "C:\Users\shuitt\.pyenv\pyenv-win\versions\3.9.6\lib\site-packages\websocket\_abnf.py", line 373, in recv_strict
    bytes_ = self.recv(min(16384, shortage))
  File "C:\Users\shuitt\.pyenv\pyenv-win\versions\3.9.6\lib\site-packages\websocket\_core.py", line 524, in _recv
    return recv(self.sock, bufsize)
  File "C:\Users\shuitt\.pyenv\pyenv-win\versions\3.9.6\lib\site-packages\websocket\_socket.py", line 122, in recv
    raise WebSocketConnectionClosedException(
websocket._exceptions.WebSocketConnectionClosedException: Connection to remote host was lost.
 (main.py)
[ERROR] 2022-08-26 17:00:54,638 - Traceback (most recent call last):
  File "C:\Users\shuitt\.pyenv\pyenv-win\versions\3.9.6\lib\site-packages\websocket\_app.py", line 383, in run_forever
    dispatcher.read(self.sock.sock, read, check)
  File "C:\Users\shuitt\.pyenv\pyenv-win\versions\3.9.6\lib\site-packages\websocket\_app.py", line 48, in read
    if not read_callback():
  File "C:\Users\shuitt\.pyenv\pyenv-win\versions\3.9.6\lib\site-packages\websocket\_app.py", line 349, in read
    op_code, frame = self.sock.recv_data_frame(True)
  File "C:\Users\shuitt\.pyenv\pyenv-win\versions\3.9.6\lib\site-packages\websocket\_core.py", line 401, in recv_data_frame
    frame = self.recv_frame()
  File "C:\Users\shuitt\.pyenv\pyenv-win\versions\3.9.6\lib\site-packages\websocket\_core.py", line 440, in recv_frame
    return self.frame_buffer.recv_frame()
  File "C:\Users\shuitt\.pyenv\pyenv-win\versions\3.9.6\lib\site-packages\websocket\_abnf.py", line 338, in recv_frame
    self.recv_header()
  File "C:\Users\shuitt\.pyenv\pyenv-win\versions\3.9.6\lib\site-packages\websocket\_abnf.py", line 294, in recv_header
    header = self.recv_strict(2)
  File "C:\Users\shuitt\.pyenv\pyenv-win\versions\3.9.6\lib\site-packages\websocket\_abnf.py", line 373, in recv_strict
    bytes_ = self.recv(min(16384, shortage))
  File "C:\Users\shuitt\.pyenv\pyenv-win\versions\3.9.6\lib\site-packages\websocket\_core.py", line 524, in _recv
    return recv(self.sock, bufsize)
  File "C:\Users\shuitt\.pyenv\pyenv-win\versions\3.9.6\lib\site-packages\websocket\_socket.py", line 122, in recv
    raise WebSocketConnectionClosedException(
websocket._exceptions.WebSocketConnectionClosedException: Connection to remote host was lost.
 (main.py)
[ERROR] 2022-08-26 17:00:56,785 - Traceback (most recent call last):
  File "C:\Users\shuitt\.pyenv\pyenv-win\versions\3.9.6\lib\site-packages\websocket\_app.py", line 383, in run_forever
    dispatcher.read(self.sock.sock, read, check)
  File "C:\Users\shuitt\.pyenv\pyenv-win\versions\3.9.6\lib\site-packages\websocket\_app.py", line 48, in read
    if not read_callback():
  File "C:\Users\shuitt\.pyenv\pyenv-win\versions\3.9.6\lib\site-packages\websocket\_app.py", line 349, in read
    op_code, frame = self.sock.recv_data_frame(True)
  File "C:\Users\shuitt\.pyenv\pyenv-win\versions\3.9.6\lib\site-packages\websocket\_core.py", line 401, in recv_data_frame
    frame = self.recv_frame()
  File "C:\Users\shuitt\.pyenv\pyenv-win\versions\3.9.6\lib\site-packages\websocket\_core.py", line 440, in recv_frame
    return self.frame_buffer.recv_frame()
  File "C:\Users\shuitt\.pyenv\pyenv-win\versions\3.9.6\lib\site-packages\websocket\_abnf.py", line 338, in recv_frame
    self.recv_header()
  File "C:\Users\shuitt\.pyenv\pyenv-win\versions\3.9.6\lib\site-packages\websocket\_abnf.py", line 294, in recv_header
    header = self.recv_strict(2)
  File "C:\Users\shuitt\.pyenv\pyenv-win\versions\3.9.6\lib\site-packages\websocket\_abnf.py", line 373, in recv_strict
    bytes_ = self.recv(min(16384, shortage))
  File "C:\Users\shuitt\.pyenv\pyenv-win\versions\3.9.6\lib\site-packages\websocket\_core.py", line 524, in _recv
    return recv(self.sock, bufsize)
  File "C:\Users\shuitt\.pyenv\pyenv-win\versions\3.9.6\lib\site-packages\websocket\_socket.py", line 122, in recv
    raise WebSocketConnectionClosedException(
websocket._exceptions.WebSocketConnectionClosedException: Connection to remote host was lost.
 (main.py)
[ERROR] 2022-08-26 17:00:59,000 - Traceback (most recent call last):
  File "C:\Users\shuitt\.pyenv\pyenv-win\versions\3.9.6\lib\site-packages\websocket\_app.py", line 383, in run_forever
    dispatcher.read(self.sock.sock, read, check)
  File "C:\Users\shuitt\.pyenv\pyenv-win\versions\3.9.6\lib\site-packages\websocket\_app.py", line 48, in read
    if not read_callback():
  File "C:\Users\shuitt\.pyenv\pyenv-win\versions\3.9.6\lib\site-packages\websocket\_app.py", line 349, in read
    op_code, frame = self.sock.recv_data_frame(True)
  File "C:\Users\shuitt\.pyenv\pyenv-win\versions\3.9.6\lib\site-packages\websocket\_core.py", line 401, in recv_data_frame
    frame = self.recv_frame()
  File "C:\Users\shuitt\.pyenv\pyenv-win\versions\3.9.6\lib\site-packages\websocket\_core.py", line 440, in recv_frame
    return self.frame_buffer.recv_frame()
  File "C:\Users\shuitt\.pyenv\pyenv-win\versions\3.9.6\lib\site-packages\websocket\_abnf.py", line 338, in recv_frame
    self.recv_header()
  File "C:\Users\shuitt\.pyenv\pyenv-win\versions\3.9.6\lib\site-packages\websocket\_abnf.py", line 294, in recv_header
    header = self.recv_strict(2)
  File "C:\Users\shuitt\.pyenv\pyenv-win\versions\3.9.6\lib\site-packages\websocket\_abnf.py", line 373, in recv_strict
    bytes_ = self.recv(min(16384, shortage))
  File "C:\Users\shuitt\.pyenv\pyenv-win\versions\3.9.6\lib\site-packages\websocket\_core.py", line 524, in _recv
    return recv(self.sock, bufsize)
  File "C:\Users\shuitt\.pyenv\pyenv-win\versions\3.9.6\lib\site-packages\websocket\_socket.py", line 122, in recv
    raise WebSocketConnectionClosedException(
websocket._exceptions.WebSocketConnectionClosedException: Connection to remote host was lost.
 (main.py)
[ERROR] 2022-08-26 17:01:01,160 - Traceback (most recent call last):
  File "C:\Users\shuitt\.pyenv\pyenv-win\versions\3.9.6\lib\site-packages\websocket\_app.py", line 383, in run_forever
    dispatcher.read(self.sock.sock, read, check)
  File "C:\Users\shuitt\.pyenv\pyenv-win\versions\3.9.6\lib\site-packages\websocket\_app.py", line 48, in read
    if not read_callback():
  File "C:\Users\shuitt\.pyenv\pyenv-win\versions\3.9.6\lib\site-packages\websocket\_app.py", line 349, in read
    op_code, frame = self.sock.recv_data_frame(True)
  File "C:\Users\shuitt\.pyenv\pyenv-win\versions\3.9.6\lib\site-packages\websocket\_core.py", line 401, in recv_data_frame
    frame = self.recv_frame()
  File "C:\Users\shuitt\.pyenv\pyenv-win\versions\3.9.6\lib\site-packages\websocket\_core.py", line 440, in recv_frame
    return self.frame_buffer.recv_frame()
  File "C:\Users\shuitt\.pyenv\pyenv-win\versions\3.9.6\lib\site-packages\websocket\_abnf.py", line 338, in recv_frame
    self.recv_header()
  File "C:\Users\shuitt\.pyenv\pyenv-win\versions\3.9.6\lib\site-packages\websocket\_abnf.py", line 294, in recv_header
    header = self.recv_strict(2)
  File "C:\Users\shuitt\.pyenv\pyenv-win\versions\3.9.6\lib\site-packages\websocket\_abnf.py", line 373, in recv_strict
    bytes_ = self.recv(min(16384, shortage))
  File "C:\Users\shuitt\.pyenv\pyenv-win\versions\3.9.6\lib\site-packages\websocket\_core.py", line 524, in _recv
    return recv(self.sock, bufsize)
  File "C:\Users\shuitt\.pyenv\pyenv-win\versions\3.9.6\lib\site-packages\websocket\_socket.py", line 122, in recv
    raise WebSocketConnectionClosedException(
websocket._exceptions.WebSocketConnectionClosedException: Connection to remote host was lost.
 (main.py)
[ERROR] 2022-08-26 17:01:03,400 - Traceback (most recent call last):
  File "C:\Users\shuitt\.pyenv\pyenv-win\versions\3.9.6\lib\site-packages\websocket\_app.py", line 383, in run_forever
    dispatcher.read(self.sock.sock, read, check)
  File "C:\Users\shuitt\.pyenv\pyenv-win\versions\3.9.6\lib\site-packages\websocket\_app.py", line 48, in read
    if not read_callback():
  File "C:\Users\shuitt\.pyenv\pyenv-win\versions\3.9.6\lib\site-packages\websocket\_app.py", line 349, in read
    op_code, frame = self.sock.recv_data_frame(True)
  File "C:\Users\shuitt\.pyenv\pyenv-win\versions\3.9.6\lib\site-packages\websocket\_core.py", line 401, in recv_data_frame
    frame = self.recv_frame()
  File "C:\Users\shuitt\.pyenv\pyenv-win\versions\3.9.6\lib\site-packages\websocket\_core.py", line 440, in recv_frame
    return self.frame_buffer.recv_frame()
  File "C:\Users\shuitt\.pyenv\pyenv-win\versions\3.9.6\lib\site-packages\websocket\_abnf.py", line 338, in recv_frame
    self.recv_header()
  File "C:\Users\shuitt\.pyenv\pyenv-win\versions\3.9.6\lib\site-packages\websocket\_abnf.py", line 294, in recv_header
    header = self.recv_strict(2)
  File "C:\Users\shuitt\.pyenv\pyenv-win\versions\3.9.6\lib\site-packages\websocket\_abnf.py", line 373, in recv_strict
    bytes_ = self.recv(min(16384, shortage))
  File "C:\Users\shuitt\.pyenv\pyenv-win\versions\3.9.6\lib\site-packages\websocket\_core.py", line 524, in _recv
    return recv(self.sock, bufsize)
  File "C:\Users\shuitt\.pyenv\pyenv-win\versions\3.9.6\lib\site-packages\websocket\_socket.py", line 122, in recv
    raise WebSocketConnectionClosedException(
websocket._exceptions.WebSocketConnectionClosedException: Connection to remote host was lost.
 (main.py)
[ERROR] 2022-08-26 17:01:03,404 - Traceback (most recent call last):
  File "C:\Users\shuitt\.pyenv\pyenv-win\versions\3.9.6\lib\site-packages\websocket\_app.py", line 383, in run_forever
    dispatcher.read(self.sock.sock, read, check)
  File "C:\Users\shuitt\.pyenv\pyenv-win\versions\3.9.6\lib\site-packages\websocket\_app.py", line 48, in read
    if not read_callback():
  File "C:\Users\shuitt\.pyenv\pyenv-win\versions\3.9.6\lib\site-packages\websocket\_app.py", line 349, in read
    op_code, frame = self.sock.recv_data_frame(True)
  File "C:\Users\shuitt\.pyenv\pyenv-win\versions\3.9.6\lib\site-packages\websocket\_core.py", line 401, in recv_data_frame
    frame = self.recv_frame()
  File "C:\Users\shuitt\.pyenv\pyenv-win\versions\3.9.6\lib\site-packages\websocket\_core.py", line 440, in recv_frame
    return self.frame_buffer.recv_frame()
  File "C:\Users\shuitt\.pyenv\pyenv-win\versions\3.9.6\lib\site-packages\websocket\_abnf.py", line 338, in recv_frame
    self.recv_header()
  File "C:\Users\shuitt\.pyenv\pyenv-win\versions\3.9.6\lib\site-packages\websocket\_abnf.py", line 294, in recv_header
    header = self.recv_strict(2)
  File "C:\Users\shuitt\.pyenv\pyenv-win\versions\3.9.6\lib\site-packages\websocket\_abnf.py", line 373, in recv_strict
    bytes_ = self.recv(min(16384, shortage))
  File "C:\Users\shuitt\.pyenv\pyenv-win\versions\3.9.6\lib\site-packages\websocket\_core.py", line 524, in _recv
    return recv(self.sock, bufsize)
  File "C:\Users\shuitt\.pyenv\pyenv-win\versions\3.9.6\lib\site-packages\websocket\_socket.py", line 122, in recv
    raise WebSocketConnectionClosedException(
websocket._exceptions.WebSocketConnectionClosedException: Connection to remote host was lost.

During handling of the above exception, another exception occurred:

Traceback (most recent call last):
  File "C:\Users\shuitt\.pyenv\pyenv-win\versions\3.9.6\lib\site-packages\websocket\_app.py", line 424, in _callback
    callback(self, *args)
TypeError: on_close() takes 1 positional argument but 3 were given
 (main.py)
[ERROR] 2022-08-26 17:01:03,425 - Traceback (most recent call last):
  File "C:\Users\shuitt\.pyenv\pyenv-win\versions\3.9.6\lib\site-packages\websocket\_app.py", line 383, in run_forever
    dispatcher.read(self.sock.sock, read, check)
  File "C:\Users\shuitt\.pyenv\pyenv-win\versions\3.9.6\lib\site-packages\websocket\_app.py", line 48, in read
    if not read_callback():
  File "C:\Users\shuitt\.pyenv\pyenv-win\versions\3.9.6\lib\site-packages\websocket\_app.py", line 349, in read
    op_code, frame = self.sock.recv_data_frame(True)
  File "C:\Users\shuitt\.pyenv\pyenv-win\versions\3.9.6\lib\site-packages\websocket\_core.py", line 401, in recv_data_frame
    frame = self.recv_frame()
  File "C:\Users\shuitt\.pyenv\pyenv-win\versions\3.9.6\lib\site-packages\websocket\_core.py", line 440, in recv_frame
    return self.frame_buffer.recv_frame()
  File "C:\Users\shuitt\.pyenv\pyenv-win\versions\3.9.6\lib\site-packages\websocket\_abnf.py", line 338, in recv_frame
    self.recv_header()
  File "C:\Users\shuitt\.pyenv\pyenv-win\versions\3.9.6\lib\site-packages\websocket\_abnf.py", line 294, in recv_header
    header = self.recv_strict(2)
  File "C:\Users\shuitt\.pyenv\pyenv-win\versions\3.9.6\lib\site-packages\websocket\_abnf.py", line 373, in recv_strict
    bytes_ = self.recv(min(16384, shortage))
  File "C:\Users\shuitt\.pyenv\pyenv-win\versions\3.9.6\lib\site-packages\websocket\_core.py", line 524, in _recv
    return recv(self.sock, bufsize)
  File "C:\Users\shuitt\.pyenv\pyenv-win\versions\3.9.6\lib\site-packages\websocket\_socket.py", line 122, in recv
    raise WebSocketConnectionClosedException(
websocket._exceptions.WebSocketConnectionClosedException: Connection to remote host was lost.

During handling of the above exception, another exception occurred:

Traceback (most recent call last):
  File "C:\Users\shuitt\.pyenv\pyenv-win\versions\3.9.6\lib\site-packages\websocket\_app.py", line 424, in _callback
    callback(self, *args)
TypeError: on_close() takes 1 positional argument but 3 were given
 (main.py)
[ERROR] 2022-08-26 17:01:05,681 - Traceback (most recent call last):
  File "C:\Users\shuitt\.pyenv\pyenv-win\versions\3.9.6\lib\site-packages\websocket\_app.py", line 383, in run_forever
    dispatcher.read(self.sock.sock, read, check)
  File "C:\Users\shuitt\.pyenv\pyenv-win\versions\3.9.6\lib\site-packages\websocket\_app.py", line 48, in read
    if not read_callback():
  File "C:\Users\shuitt\.pyenv\pyenv-win\versions\3.9.6\lib\site-packages\websocket\_app.py", line 349, in read
    op_code, frame = self.sock.recv_data_frame(True)
  File "C:\Users\shuitt\.pyenv\pyenv-win\versions\3.9.6\lib\site-packages\websocket\_core.py", line 401, in recv_data_frame
    frame = self.recv_frame()
  File "C:\Users\shuitt\.pyenv\pyenv-win\versions\3.9.6\lib\site-packages\websocket\_core.py", line 440, in recv_frame
    return self.frame_buffer.recv_frame()
  File "C:\Users\shuitt\.pyenv\pyenv-win\versions\3.9.6\lib\site-packages\websocket\_abnf.py", line 338, in recv_frame
    self.recv_header()
  File "C:\Users\shuitt\.pyenv\pyenv-win\versions\3.9.6\lib\site-packages\websocket\_abnf.py", line 294, in recv_header
    header = self.recv_strict(2)
  File "C:\Users\shuitt\.pyenv\pyenv-win\versions\3.9.6\lib\site-packages\websocket\_abnf.py", line 373, in recv_strict
    bytes_ = self.recv(min(16384, shortage))
  File "C:\Users\shuitt\.pyenv\pyenv-win\versions\3.9.6\lib\site-packages\websocket\_core.py", line 524, in _recv
    return recv(self.sock, bufsize)
  File "C:\Users\shuitt\.pyenv\pyenv-win\versions\3.9.6\lib\site-packages\websocket\_socket.py", line 122, in recv
    raise WebSocketConnectionClosedException(
websocket._exceptions.WebSocketConnectionClosedException: Connection to remote host was lost.
 (main.py)
[ERROR] 2022-08-26 17:01:05,684 - Traceback (most recent call last):
  File "C:\Users\shuitt\.pyenv\pyenv-win\versions\3.9.6\lib\site-packages\websocket\_app.py", line 383, in run_forever
    dispatcher.read(self.sock.sock, read, check)
  File "C:\Users\shuitt\.pyenv\pyenv-win\versions\3.9.6\lib\site-packages\websocket\_app.py", line 48, in read
    if not read_callback():
  File "C:\Users\shuitt\.pyenv\pyenv-win\versions\3.9.6\lib\site-packages\websocket\_app.py", line 349, in read
    op_code, frame = self.sock.recv_data_frame(True)
  File "C:\Users\shuitt\.pyenv\pyenv-win\versions\3.9.6\lib\site-packages\websocket\_core.py", line 401, in recv_data_frame
    frame = self.recv_frame()
  File "C:\Users\shuitt\.pyenv\pyenv-win\versions\3.9.6\lib\site-packages\websocket\_core.py", line 440, in recv_frame
    return self.frame_buffer.recv_frame()
  File "C:\Users\shuitt\.pyenv\pyenv-win\versions\3.9.6\lib\site-packages\websocket\_abnf.py", line 338, in recv_frame
    self.recv_header()
  File "C:\Users\shuitt\.pyenv\pyenv-win\versions\3.9.6\lib\site-packages\websocket\_abnf.py", line 294, in recv_header
    header = self.recv_strict(2)
  File "C:\Users\shuitt\.pyenv\pyenv-win\versions\3.9.6\lib\site-packages\websocket\_abnf.py", line 373, in recv_strict
    bytes_ = self.recv(min(16384, shortage))
  File "C:\Users\shuitt\.pyenv\pyenv-win\versions\3.9.6\lib\site-packages\websocket\_core.py", line 524, in _recv
    return recv(self.sock, bufsize)
  File "C:\Users\shuitt\.pyenv\pyenv-win\versions\3.9.6\lib\site-packages\websocket\_socket.py", line 122, in recv
    raise WebSocketConnectionClosedException(
websocket._exceptions.WebSocketConnectionClosedException: Connection to remote host was lost.

During handling of the above exception, another exception occurred:

Traceback (most recent call last):
  File "C:\Users\shuitt\.pyenv\pyenv-win\versions\3.9.6\lib\site-packages\websocket\_app.py", line 424, in _callback
    callback(self, *args)
TypeError: on_close() takes 1 positional argument but 3 were given
 (main.py)
[ERROR] 2022-08-26 17:01:05,714 - Traceback (most recent call last):
  File "C:\Users\shuitt\.pyenv\pyenv-win\versions\3.9.6\lib\site-packages\websocket\_app.py", line 383, in run_forever
    dispatcher.read(self.sock.sock, read, check)
  File "C:\Users\shuitt\.pyenv\pyenv-win\versions\3.9.6\lib\site-packages\websocket\_app.py", line 48, in read
    if not read_callback():
  File "C:\Users\shuitt\.pyenv\pyenv-win\versions\3.9.6\lib\site-packages\websocket\_app.py", line 349, in read
    op_code, frame = self.sock.recv_data_frame(True)
  File "C:\Users\shuitt\.pyenv\pyenv-win\versions\3.9.6\lib\site-packages\websocket\_core.py", line 401, in recv_data_frame
    frame = self.recv_frame()
  File "C:\Users\shuitt\.pyenv\pyenv-win\versions\3.9.6\lib\site-packages\websocket\_core.py", line 440, in recv_frame
    return self.frame_buffer.recv_frame()
  File "C:\Users\shuitt\.pyenv\pyenv-win\versions\3.9.6\lib\site-packages\websocket\_abnf.py", line 338, in recv_frame
    self.recv_header()
  File "C:\Users\shuitt\.pyenv\pyenv-win\versions\3.9.6\lib\site-packages\websocket\_abnf.py", line 294, in recv_header
    header = self.recv_strict(2)
  File "C:\Users\shuitt\.pyenv\pyenv-win\versions\3.9.6\lib\site-packages\websocket\_abnf.py", line 373, in recv_strict
    bytes_ = self.recv(min(16384, shortage))
  File "C:\Users\shuitt\.pyenv\pyenv-win\versions\3.9.6\lib\site-packages\websocket\_core.py", line 524, in _recv
    return recv(self.sock, bufsize)
  File "C:\Users\shuitt\.pyenv\pyenv-win\versions\3.9.6\lib\site-packages\websocket\_socket.py", line 122, in recv
    raise WebSocketConnectionClosedException(
websocket._exceptions.WebSocketConnectionClosedException: Connection to remote host was lost.

During handling of the above exception, another exception occurred:

Traceback (most recent call last):
  File "C:\Users\shuitt\.pyenv\pyenv-win\versions\3.9.6\lib\site-packages\websocket\_app.py", line 424, in _callback
    callback(self, *args)
TypeError: on_close() takes 1 positional argument but 3 were given
 (main.py)
[ERROR] 2022-08-26 17:01:07,876 - Traceback (most recent call last):
  File "C:\Users\shuitt\.pyenv\pyenv-win\versions\3.9.6\lib\site-packages\websocket\_app.py", line 383, in run_forever
    dispatcher.read(self.sock.sock, read, check)
  File "C:\Users\shuitt\.pyenv\pyenv-win\versions\3.9.6\lib\site-packages\websocket\_app.py", line 48, in read
    if not read_callback():
  File "C:\Users\shuitt\.pyenv\pyenv-win\versions\3.9.6\lib\site-packages\websocket\_app.py", line 349, in read
    op_code, frame = self.sock.recv_data_frame(True)
  File "C:\Users\shuitt\.pyenv\pyenv-win\versions\3.9.6\lib\site-packages\websocket\_core.py", line 401, in recv_data_frame
    frame = self.recv_frame()
  File "C:\Users\shuitt\.pyenv\pyenv-win\versions\3.9.6\lib\site-packages\websocket\_core.py", line 440, in recv_frame
    return self.frame_buffer.recv_frame()
  File "C:\Users\shuitt\.pyenv\pyenv-win\versions\3.9.6\lib\site-packages\websocket\_abnf.py", line 338, in recv_frame
    self.recv_header()
  File "C:\Users\shuitt\.pyenv\pyenv-win\versions\3.9.6\lib\site-packages\websocket\_abnf.py", line 294, in recv_header
    header = self.recv_strict(2)
  File "C:\Users\shuitt\.pyenv\pyenv-win\versions\3.9.6\lib\site-packages\websocket\_abnf.py", line 373, in recv_strict
    bytes_ = self.recv(min(16384, shortage))
  File "C:\Users\shuitt\.pyenv\pyenv-win\versions\3.9.6\lib\site-packages\websocket\_core.py", line 524, in _recv
    return recv(self.sock, bufsize)
  File "C:\Users\shuitt\.pyenv\pyenv-win\versions\3.9.6\lib\site-packages\websocket\_socket.py", line 122, in recv
    raise WebSocketConnectionClosedException(
websocket._exceptions.WebSocketConnectionClosedException: Connection to remote host was lost.
 (main.py)
[ERROR] 2022-08-26 17:01:07,877 - Traceback (most recent call last):
  File "C:\Users\shuitt\.pyenv\pyenv-win\versions\3.9.6\lib\site-packages\websocket\_app.py", line 383, in run_forever
    dispatcher.read(self.sock.sock, read, check)
  File "C:\Users\shuitt\.pyenv\pyenv-win\versions\3.9.6\lib\site-packages\websocket\_app.py", line 48, in read
    if not read_callback():
  File "C:\Users\shuitt\.pyenv\pyenv-win\versions\3.9.6\lib\site-packages\websocket\_app.py", line 349, in read
    op_code, frame = self.sock.recv_data_frame(True)
  File "C:\Users\shuitt\.pyenv\pyenv-win\versions\3.9.6\lib\site-packages\websocket\_core.py", line 401, in recv_data_frame
    frame = self.recv_frame()
  File "C:\Users\shuitt\.pyenv\pyenv-win\versions\3.9.6\lib\site-packages\websocket\_core.py", line 440, in recv_frame
    return self.frame_buffer.recv_frame()
  File "C:\Users\shuitt\.pyenv\pyenv-win\versions\3.9.6\lib\site-packages\websocket\_abnf.py", line 338, in recv_frame
    self.recv_header()
  File "C:\Users\shuitt\.pyenv\pyenv-win\versions\3.9.6\lib\site-packages\websocket\_abnf.py", line 294, in recv_header
    header = self.recv_strict(2)
  File "C:\Users\shuitt\.pyenv\pyenv-win\versions\3.9.6\lib\site-packages\websocket\_abnf.py", line 373, in recv_strict
    bytes_ = self.recv(min(16384, shortage))
  File "C:\Users\shuitt\.pyenv\pyenv-win\versions\3.9.6\lib\site-packages\websocket\_core.py", line 524, in _recv
    return recv(self.sock, bufsize)
  File "C:\Users\shuitt\.pyenv\pyenv-win\versions\3.9.6\lib\site-packages\websocket\_socket.py", line 122, in recv
    raise WebSocketConnectionClosedException(
websocket._exceptions.WebSocketConnectionClosedException: Connection to remote host was lost.

During handling of the above exception, another exception occurred:

Traceback (most recent call last):
  File "C:\Users\shuitt\.pyenv\pyenv-win\versions\3.9.6\lib\site-packages\websocket\_app.py", line 424, in _callback
    callback(self, *args)
TypeError: on_close() takes 1 positional argument but 3 were given
 (main.py)
[ERROR] 2022-08-26 17:01:07,896 - Traceback (most recent call last):
  File "C:\Users\shuitt\.pyenv\pyenv-win\versions\3.9.6\lib\site-packages\websocket\_app.py", line 383, in run_forever
    dispatcher.read(self.sock.sock, read, check)
  File "C:\Users\shuitt\.pyenv\pyenv-win\versions\3.9.6\lib\site-packages\websocket\_app.py", line 48, in read
    if not read_callback():
  File "C:\Users\shuitt\.pyenv\pyenv-win\versions\3.9.6\lib\site-packages\websocket\_app.py", line 349, in read
    op_code, frame = self.sock.recv_data_frame(True)
  File "C:\Users\shuitt\.pyenv\pyenv-win\versions\3.9.6\lib\site-packages\websocket\_core.py", line 401, in recv_data_frame
    frame = self.recv_frame()
  File "C:\Users\shuitt\.pyenv\pyenv-win\versions\3.9.6\lib\site-packages\websocket\_core.py", line 440, in recv_frame
    return self.frame_buffer.recv_frame()
  File "C:\Users\shuitt\.pyenv\pyenv-win\versions\3.9.6\lib\site-packages\websocket\_abnf.py", line 338, in recv_frame
    self.recv_header()
  File "C:\Users\shuitt\.pyenv\pyenv-win\versions\3.9.6\lib\site-packages\websocket\_abnf.py", line 294, in recv_header
    header = self.recv_strict(2)
  File "C:\Users\shuitt\.pyenv\pyenv-win\versions\3.9.6\lib\site-packages\websocket\_abnf.py", line 373, in recv_strict
    bytes_ = self.recv(min(16384, shortage))
  File "C:\Users\shuitt\.pyenv\pyenv-win\versions\3.9.6\lib\site-packages\websocket\_core.py", line 524, in _recv
    return recv(self.sock, bufsize)
  File "C:\Users\shuitt\.pyenv\pyenv-win\versions\3.9.6\lib\site-packages\websocket\_socket.py", line 122, in recv
    raise WebSocketConnectionClosedException(
websocket._exceptions.WebSocketConnectionClosedException: Connection to remote host was lost.

During handling of the above exception, another exception occurred:

Traceback (most recent call last):
  File "C:\Users\shuitt\.pyenv\pyenv-win\versions\3.9.6\lib\site-packages\websocket\_app.py", line 424, in _callback
    callback(self, *args)
TypeError: on_close() takes 1 positional argument but 3 were given
 (main.py)
[ERROR] 2022-08-26 17:01:10,079 - Traceback (most recent call last):
  File "C:\Users\shuitt\.pyenv\pyenv-win\versions\3.9.6\lib\site-packages\websocket\_app.py", line 383, in run_forever
    dispatcher.read(self.sock.sock, read, check)
  File "C:\Users\shuitt\.pyenv\pyenv-win\versions\3.9.6\lib\site-packages\websocket\_app.py", line 48, in read
    if not read_callback():
  File "C:\Users\shuitt\.pyenv\pyenv-win\versions\3.9.6\lib\site-packages\websocket\_app.py", line 349, in read
    op_code, frame = self.sock.recv_data_frame(True)
  File "C:\Users\shuitt\.pyenv\pyenv-win\versions\3.9.6\lib\site-packages\websocket\_core.py", line 401, in recv_data_frame
    frame = self.recv_frame()
  File "C:\Users\shuitt\.pyenv\pyenv-win\versions\3.9.6\lib\site-packages\websocket\_core.py", line 440, in recv_frame
    return self.frame_buffer.recv_frame()
  File "C:\Users\shuitt\.pyenv\pyenv-win\versions\3.9.6\lib\site-packages\websocket\_abnf.py", line 338, in recv_frame
    self.recv_header()
  File "C:\Users\shuitt\.pyenv\pyenv-win\versions\3.9.6\lib\site-packages\websocket\_abnf.py", line 294, in recv_header
    header = self.recv_strict(2)
  File "C:\Users\shuitt\.pyenv\pyenv-win\versions\3.9.6\lib\site-packages\websocket\_abnf.py", line 373, in recv_strict
    bytes_ = self.recv(min(16384, shortage))
  File "C:\Users\shuitt\.pyenv\pyenv-win\versions\3.9.6\lib\site-packages\websocket\_core.py", line 524, in _recv
    return recv(self.sock, bufsize)
  File "C:\Users\shuitt\.pyenv\pyenv-win\versions\3.9.6\lib\site-packages\websocket\_socket.py", line 122, in recv
    raise WebSocketConnectionClosedException(
websocket._exceptions.WebSocketConnectionClosedException: Connection to remote host was lost.
 (main.py)
[ERROR] 2022-08-26 17:01:10,082 - Traceback (most recent call last):
  File "C:\Users\shuitt\.pyenv\pyenv-win\versions\3.9.6\lib\site-packages\websocket\_app.py", line 383, in run_forever
    dispatcher.read(self.sock.sock, read, check)
  File "C:\Users\shuitt\.pyenv\pyenv-win\versions\3.9.6\lib\site-packages\websocket\_app.py", line 48, in read
    if not read_callback():
  File "C:\Users\shuitt\.pyenv\pyenv-win\versions\3.9.6\lib\site-packages\websocket\_app.py", line 349, in read
    op_code, frame = self.sock.recv_data_frame(True)
  File "C:\Users\shuitt\.pyenv\pyenv-win\versions\3.9.6\lib\site-packages\websocket\_core.py", line 401, in recv_data_frame
    frame = self.recv_frame()
  File "C:\Users\shuitt\.pyenv\pyenv-win\versions\3.9.6\lib\site-packages\websocket\_core.py", line 440, in recv_frame
    return self.frame_buffer.recv_frame()
  File "C:\Users\shuitt\.pyenv\pyenv-win\versions\3.9.6\lib\site-packages\websocket\_abnf.py", line 338, in recv_frame
    self.recv_header()
  File "C:\Users\shuitt\.pyenv\pyenv-win\versions\3.9.6\lib\site-packages\websocket\_abnf.py", line 294, in recv_header
    header = self.recv_strict(2)
  File "C:\Users\shuitt\.pyenv\pyenv-win\versions\3.9.6\lib\site-packages\websocket\_abnf.py", line 373, in recv_strict
    bytes_ = self.recv(min(16384, shortage))
  File "C:\Users\shuitt\.pyenv\pyenv-win\versions\3.9.6\lib\site-packages\websocket\_core.py", line 524, in _recv
    return recv(self.sock, bufsize)
  File "C:\Users\shuitt\.pyenv\pyenv-win\versions\3.9.6\lib\site-packages\websocket\_socket.py", line 122, in recv
    raise WebSocketConnectionClosedException(
websocket._exceptions.WebSocketConnectionClosedException: Connection to remote host was lost.

During handling of the above exception, another exception occurred:

Traceback (most recent call last):
  File "C:\Users\shuitt\.pyenv\pyenv-win\versions\3.9.6\lib\site-packages\websocket\_app.py", line 424, in _callback
    callback(self, *args)
TypeError: on_close() takes 1 positional argument but 3 were given
 (main.py)
[ERROR] 2022-08-26 17:01:10,108 - Traceback (most recent call last):
  File "C:\Users\shuitt\.pyenv\pyenv-win\versions\3.9.6\lib\site-packages\websocket\_app.py", line 383, in run_forever
    dispatcher.read(self.sock.sock, read, check)
  File "C:\Users\shuitt\.pyenv\pyenv-win\versions\3.9.6\lib\site-packages\websocket\_app.py", line 48, in read
    if not read_callback():
  File "C:\Users\shuitt\.pyenv\pyenv-win\versions\3.9.6\lib\site-packages\websocket\_app.py", line 349, in read
    op_code, frame = self.sock.recv_data_frame(True)
  File "C:\Users\shuitt\.pyenv\pyenv-win\versions\3.9.6\lib\site-packages\websocket\_core.py", line 401, in recv_data_frame
    frame = self.recv_frame()
  File "C:\Users\shuitt\.pyenv\pyenv-win\versions\3.9.6\lib\site-packages\websocket\_core.py", line 440, in recv_frame
    return self.frame_buffer.recv_frame()
  File "C:\Users\shuitt\.pyenv\pyenv-win\versions\3.9.6\lib\site-packages\websocket\_abnf.py", line 338, in recv_frame
    self.recv_header()
  File "C:\Users\shuitt\.pyenv\pyenv-win\versions\3.9.6\lib\site-packages\websocket\_abnf.py", line 294, in recv_header
    header = self.recv_strict(2)
  File "C:\Users\shuitt\.pyenv\pyenv-win\versions\3.9.6\lib\site-packages\websocket\_abnf.py", line 373, in recv_strict
    bytes_ = self.recv(min(16384, shortage))
  File "C:\Users\shuitt\.pyenv\pyenv-win\versions\3.9.6\lib\site-packages\websocket\_core.py", line 524, in _recv
    return recv(self.sock, bufsize)
  File "C:\Users\shuitt\.pyenv\pyenv-win\versions\3.9.6\lib\site-packages\websocket\_socket.py", line 122, in recv
    raise WebSocketConnectionClosedException(
websocket._exceptions.WebSocketConnectionClosedException: Connection to remote host was lost.

During handling of the above exception, another exception occurred:

Traceback (most recent call last):
  File "C:\Users\shuitt\.pyenv\pyenv-win\versions\3.9.6\lib\site-packages\websocket\_app.py", line 424, in _callback
    callback(self, *args)
TypeError: on_close() takes 1 positional argument but 3 were given
 (main.py)
[ERROR] 2022-08-26 17:01:51,968 - Traceback (most recent call last):
  File "C:\Users\shuitt\.pyenv\pyenv-win\versions\3.9.6\lib\site-packages\websocket\_app.py", line 383, in run_forever
    dispatcher.read(self.sock.sock, read, check)
  File "C:\Users\shuitt\.pyenv\pyenv-win\versions\3.9.6\lib\site-packages\websocket\_app.py", line 48, in read
    if not read_callback():
  File "C:\Users\shuitt\.pyenv\pyenv-win\versions\3.9.6\lib\site-packages\websocket\_app.py", line 349, in read
    op_code, frame = self.sock.recv_data_frame(True)
  File "C:\Users\shuitt\.pyenv\pyenv-win\versions\3.9.6\lib\site-packages\websocket\_core.py", line 401, in recv_data_frame
    frame = self.recv_frame()
  File "C:\Users\shuitt\.pyenv\pyenv-win\versions\3.9.6\lib\site-packages\websocket\_core.py", line 440, in recv_frame
    return self.frame_buffer.recv_frame()
  File "C:\Users\shuitt\.pyenv\pyenv-win\versions\3.9.6\lib\site-packages\websocket\_abnf.py", line 338, in recv_frame
    self.recv_header()
  File "C:\Users\shuitt\.pyenv\pyenv-win\versions\3.9.6\lib\site-packages\websocket\_abnf.py", line 294, in recv_header
    header = self.recv_strict(2)
  File "C:\Users\shuitt\.pyenv\pyenv-win\versions\3.9.6\lib\site-packages\websocket\_abnf.py", line 373, in recv_strict
    bytes_ = self.recv(min(16384, shortage))
  File "C:\Users\shuitt\.pyenv\pyenv-win\versions\3.9.6\lib\site-packages\websocket\_core.py", line 524, in _recv
    return recv(self.sock, bufsize)
  File "C:\Users\shuitt\.pyenv\pyenv-win\versions\3.9.6\lib\site-packages\websocket\_socket.py", line 122, in recv
    raise WebSocketConnectionClosedException(
websocket._exceptions.WebSocketConnectionClosedException: Connection to remote host was lost.
 (main.py)
[ERROR] 2022-08-26 17:01:51,972 - Traceback (most recent call last):
  File "C:\Users\shuitt\.pyenv\pyenv-win\versions\3.9.6\lib\site-packages\websocket\_app.py", line 383, in run_forever
    dispatcher.read(self.sock.sock, read, check)
  File "C:\Users\shuitt\.pyenv\pyenv-win\versions\3.9.6\lib\site-packages\websocket\_app.py", line 48, in read
    if not read_callback():
  File "C:\Users\shuitt\.pyenv\pyenv-win\versions\3.9.6\lib\site-packages\websocket\_app.py", line 349, in read
    op_code, frame = self.sock.recv_data_frame(True)
  File "C:\Users\shuitt\.pyenv\pyenv-win\versions\3.9.6\lib\site-packages\websocket\_core.py", line 401, in recv_data_frame
    frame = self.recv_frame()
  File "C:\Users\shuitt\.pyenv\pyenv-win\versions\3.9.6\lib\site-packages\websocket\_core.py", line 440, in recv_frame
    return self.frame_buffer.recv_frame()
  File "C:\Users\shuitt\.pyenv\pyenv-win\versions\3.9.6\lib\site-packages\websocket\_abnf.py", line 338, in recv_frame
    self.recv_header()
  File "C:\Users\shuitt\.pyenv\pyenv-win\versions\3.9.6\lib\site-packages\websocket\_abnf.py", line 294, in recv_header
    header = self.recv_strict(2)
  File "C:\Users\shuitt\.pyenv\pyenv-win\versions\3.9.6\lib\site-packages\websocket\_abnf.py", line 373, in recv_strict
    bytes_ = self.recv(min(16384, shortage))
  File "C:\Users\shuitt\.pyenv\pyenv-win\versions\3.9.6\lib\site-packages\websocket\_core.py", line 524, in _recv
    return recv(self.sock, bufsize)
  File "C:\Users\shuitt\.pyenv\pyenv-win\versions\3.9.6\lib\site-packages\websocket\_socket.py", line 122, in recv
    raise WebSocketConnectionClosedException(
websocket._exceptions.WebSocketConnectionClosedException: Connection to remote host was lost.

During handling of the above exception, another exception occurred:

Traceback (most recent call last):
  File "C:\Users\shuitt\.pyenv\pyenv-win\versions\3.9.6\lib\site-packages\websocket\_app.py", line 424, in _callback
    callback(self, *args)
TypeError: on_close() takes 1 positional argument but 3 were given
 (main.py)
[ERROR] 2022-08-26 17:03:11,067 - Traceback (most recent call last):
  File "C:\Users\shuitt\.pyenv\pyenv-win\versions\3.9.6\lib\site-packages\websocket\_app.py", line 383, in run_forever
    dispatcher.read(self.sock.sock, read, check)
  File "C:\Users\shuitt\.pyenv\pyenv-win\versions\3.9.6\lib\site-packages\websocket\_app.py", line 48, in read
    if not read_callback():
  File "C:\Users\shuitt\.pyenv\pyenv-win\versions\3.9.6\lib\site-packages\websocket\_app.py", line 349, in read
    op_code, frame = self.sock.recv_data_frame(True)
  File "C:\Users\shuitt\.pyenv\pyenv-win\versions\3.9.6\lib\site-packages\websocket\_core.py", line 401, in recv_data_frame
    frame = self.recv_frame()
  File "C:\Users\shuitt\.pyenv\pyenv-win\versions\3.9.6\lib\site-packages\websocket\_core.py", line 440, in recv_frame
    return self.frame_buffer.recv_frame()
  File "C:\Users\shuitt\.pyenv\pyenv-win\versions\3.9.6\lib\site-packages\websocket\_abnf.py", line 338, in recv_frame
    self.recv_header()
  File "C:\Users\shuitt\.pyenv\pyenv-win\versions\3.9.6\lib\site-packages\websocket\_abnf.py", line 294, in recv_header
    header = self.recv_strict(2)
  File "C:\Users\shuitt\.pyenv\pyenv-win\versions\3.9.6\lib\site-packages\websocket\_abnf.py", line 373, in recv_strict
    bytes_ = self.recv(min(16384, shortage))
  File "C:\Users\shuitt\.pyenv\pyenv-win\versions\3.9.6\lib\site-packages\websocket\_core.py", line 524, in _recv
    return recv(self.sock, bufsize)
  File "C:\Users\shuitt\.pyenv\pyenv-win\versions\3.9.6\lib\site-packages\websocket\_socket.py", line 122, in recv
    raise WebSocketConnectionClosedException(
websocket._exceptions.WebSocketConnectionClosedException: Connection to remote host was lost.
 (main.py)
[ERROR] 2022-08-26 17:03:13,233 - Traceback (most recent call last):
  File "C:\Users\shuitt\.pyenv\pyenv-win\versions\3.9.6\lib\site-packages\websocket\_app.py", line 383, in run_forever
    dispatcher.read(self.sock.sock, read, check)
  File "C:\Users\shuitt\.pyenv\pyenv-win\versions\3.9.6\lib\site-packages\websocket\_app.py", line 48, in read
    if not read_callback():
  File "C:\Users\shuitt\.pyenv\pyenv-win\versions\3.9.6\lib\site-packages\websocket\_app.py", line 349, in read
    op_code, frame = self.sock.recv_data_frame(True)
  File "C:\Users\shuitt\.pyenv\pyenv-win\versions\3.9.6\lib\site-packages\websocket\_core.py", line 401, in recv_data_frame
    frame = self.recv_frame()
  File "C:\Users\shuitt\.pyenv\pyenv-win\versions\3.9.6\lib\site-packages\websocket\_core.py", line 440, in recv_frame
    return self.frame_buffer.recv_frame()
  File "C:\Users\shuitt\.pyenv\pyenv-win\versions\3.9.6\lib\site-packages\websocket\_abnf.py", line 338, in recv_frame
    self.recv_header()
  File "C:\Users\shuitt\.pyenv\pyenv-win\versions\3.9.6\lib\site-packages\websocket\_abnf.py", line 294, in recv_header
    header = self.recv_strict(2)
  File "C:\Users\shuitt\.pyenv\pyenv-win\versions\3.9.6\lib\site-packages\websocket\_abnf.py", line 373, in recv_strict
    bytes_ = self.recv(min(16384, shortage))
  File "C:\Users\shuitt\.pyenv\pyenv-win\versions\3.9.6\lib\site-packages\websocket\_core.py", line 524, in _recv
    return recv(self.sock, bufsize)
  File "C:\Users\shuitt\.pyenv\pyenv-win\versions\3.9.6\lib\site-packages\websocket\_socket.py", line 122, in recv
    raise WebSocketConnectionClosedException(
websocket._exceptions.WebSocketConnectionClosedException: Connection to remote host was lost.
 (main.py)
[ERROR] 2022-08-26 17:03:15,451 - Traceback (most recent call last):
  File "C:\Users\shuitt\.pyenv\pyenv-win\versions\3.9.6\lib\site-packages\websocket\_app.py", line 383, in run_forever
    dispatcher.read(self.sock.sock, read, check)
  File "C:\Users\shuitt\.pyenv\pyenv-win\versions\3.9.6\lib\site-packages\websocket\_app.py", line 48, in read
    if not read_callback():
  File "C:\Users\shuitt\.pyenv\pyenv-win\versions\3.9.6\lib\site-packages\websocket\_app.py", line 349, in read
    op_code, frame = self.sock.recv_data_frame(True)
  File "C:\Users\shuitt\.pyenv\pyenv-win\versions\3.9.6\lib\site-packages\websocket\_core.py", line 401, in recv_data_frame
    frame = self.recv_frame()
  File "C:\Users\shuitt\.pyenv\pyenv-win\versions\3.9.6\lib\site-packages\websocket\_core.py", line 440, in recv_frame
    return self.frame_buffer.recv_frame()
  File "C:\Users\shuitt\.pyenv\pyenv-win\versions\3.9.6\lib\site-packages\websocket\_abnf.py", line 338, in recv_frame
    self.recv_header()
  File "C:\Users\shuitt\.pyenv\pyenv-win\versions\3.9.6\lib\site-packages\websocket\_abnf.py", line 294, in recv_header
    header = self.recv_strict(2)
  File "C:\Users\shuitt\.pyenv\pyenv-win\versions\3.9.6\lib\site-packages\websocket\_abnf.py", line 373, in recv_strict
    bytes_ = self.recv(min(16384, shortage))
  File "C:\Users\shuitt\.pyenv\pyenv-win\versions\3.9.6\lib\site-packages\websocket\_core.py", line 524, in _recv
    return recv(self.sock, bufsize)
  File "C:\Users\shuitt\.pyenv\pyenv-win\versions\3.9.6\lib\site-packages\websocket\_socket.py", line 122, in recv
    raise WebSocketConnectionClosedException(
websocket._exceptions.WebSocketConnectionClosedException: Connection to remote host was lost.
 (main.py)
[ERROR] 2022-08-26 17:03:17,589 - Traceback (most recent call last):
  File "C:\Users\shuitt\.pyenv\pyenv-win\versions\3.9.6\lib\site-packages\websocket\_app.py", line 383, in run_forever
    dispatcher.read(self.sock.sock, read, check)
  File "C:\Users\shuitt\.pyenv\pyenv-win\versions\3.9.6\lib\site-packages\websocket\_app.py", line 48, in read
    if not read_callback():
  File "C:\Users\shuitt\.pyenv\pyenv-win\versions\3.9.6\lib\site-packages\websocket\_app.py", line 349, in read
    op_code, frame = self.sock.recv_data_frame(True)
  File "C:\Users\shuitt\.pyenv\pyenv-win\versions\3.9.6\lib\site-packages\websocket\_core.py", line 401, in recv_data_frame
    frame = self.recv_frame()
  File "C:\Users\shuitt\.pyenv\pyenv-win\versions\3.9.6\lib\site-packages\websocket\_core.py", line 440, in recv_frame
    return self.frame_buffer.recv_frame()
  File "C:\Users\shuitt\.pyenv\pyenv-win\versions\3.9.6\lib\site-packages\websocket\_abnf.py", line 338, in recv_frame
    self.recv_header()
  File "C:\Users\shuitt\.pyenv\pyenv-win\versions\3.9.6\lib\site-packages\websocket\_abnf.py", line 294, in recv_header
    header = self.recv_strict(2)
  File "C:\Users\shuitt\.pyenv\pyenv-win\versions\3.9.6\lib\site-packages\websocket\_abnf.py", line 373, in recv_strict
    bytes_ = self.recv(min(16384, shortage))
  File "C:\Users\shuitt\.pyenv\pyenv-win\versions\3.9.6\lib\site-packages\websocket\_core.py", line 524, in _recv
    return recv(self.sock, bufsize)
  File "C:\Users\shuitt\.pyenv\pyenv-win\versions\3.9.6\lib\site-packages\websocket\_socket.py", line 122, in recv
    raise WebSocketConnectionClosedException(
websocket._exceptions.WebSocketConnectionClosedException: Connection to remote host was lost.
 (main.py)
