[ERROR] 2022-09-10 06:39:52,010 - Traceback (most recent call last):
  File "C:\Users\shuitt\.pyenv\pyenv-win\versions\3.9.6\lib\site-packages\websocket\_app.py", line 383, in run_forever
    dispatcher.read(self.sock.sock, read, check)
  File "C:\Users\shuitt\.pyenv\pyenv-win\versions\3.9.6\lib\site-packages\websocket\_app.py", line 48, in read
    if not read_callback():
  File "C:\Users\shuitt\.pyenv\pyenv-win\versions\3.9.6\lib\site-packages\websocket\_app.py", line 349, in read
    op_code, frame = self.sock.recv_data_frame(True)
  File "C:\Users\shuitt\.pyenv\pyenv-win\versions\3.9.6\lib\site-packages\websocket\_core.py", line 401, in recv_data_frame
    frame = self.recv_frame()
  File "C:\Users\shuitt\.pyenv\pyenv-win\versions\3.9.6\lib\site-packages\websocket\_core.py", line 440, in recv_frame
    return self.frame_buffer.recv_frame()
  File "C:\Users\shuitt\.pyenv\pyenv-win\versions\3.9.6\lib\site-packages\websocket\_abnf.py", line 338, in recv_frame
    self.recv_header()
  File "C:\Users\shuitt\.pyenv\pyenv-win\versions\3.9.6\lib\site-packages\websocket\_abnf.py", line 294, in recv_header
    header = self.recv_strict(2)
  File "C:\Users\shuitt\.pyenv\pyenv-win\versions\3.9.6\lib\site-packages\websocket\_abnf.py", line 373, in recv_strict
    bytes_ = self.recv(min(16384, shortage))
  File "C:\Users\shuitt\.pyenv\pyenv-win\versions\3.9.6\lib\site-packages\websocket\_core.py", line 524, in _recv
    return recv(self.sock, bufsize)
  File "C:\Users\shuitt\.pyenv\pyenv-win\versions\3.9.6\lib\site-packages\websocket\_socket.py", line 108, in recv
    bytes_ = _recv()
  File "C:\Users\shuitt\.pyenv\pyenv-win\versions\3.9.6\lib\site-packages\websocket\_socket.py", line 87, in _recv
    return sock.recv(bufsize)
ConnectionResetError: [WinError 10054] 既存の接続はリモート ホストに強制的に切断されました。
 (main.py)
